Workbook

Sheet Ranking
B2: Player | C2: H2H (15%) | D2: Results (85%) | E2: Arknights of Terra (0%) | G2: Total | J2: Raw H2H Score | L2: Fixed H2H Score | O2: Raw Results Score | Q2: Fixed Results Score | T2: Ordered Results
B3: =PuntosBraacket!A1 -> Saihara | C3: =L3*0.15 -> 15 | D3: =Q3*0.85 -> 85 | G3: =C3+D3+E3 -> 100 | H3: 1 | J3: =PuntosBraacket!B1 -> 1827 | L3: =(J3*100/J3) -> 100 | O3: =PlayerResults!B69 -> 3136 | Q3: =(O3*100)/$O$3 -> 100 | S3: 1 | T3: Saihara | U3: 3136
B4: =PuntosBraacket!A2 -> Tormen | C4: =L4*0.15 -> 14.638752 | D4: =Q4*0.85 -> 74.164939 | G4: =C4+D4+E4 -> 88.803691 | H4: 2 | J4: =PuntosBraacket!B2 -> 1783 | L4: =(J4*100/J3) -> 97.59168 | M4: =(J4*100)/$J$4 -> 100 | O4: =PlayerResults!D69 -> 2736.25 | Q4: =(O4*100)/$O$3 -> 87.25287 | S4: 2 | T4: Tormen | U4: 2736.25
B5: =PuntosBraacket!A3 -> El Juancho | C5: =L5*0.15 -> 13.702791 | D5: =Q5*0.85 -> 65.2272 | G5: =C5+D5+E5 -> 78.929992 | H5: 3 | J5: =PuntosBraacket!B3 -> 1669 | L5: =(J5*100/J3) -> 91.351943 | M5: =(J5*100)/$J$4 -> 93.606282 | O5: =PlayerResults!C69 -> 2406.5 | Q5: =(O5*100)/$O$3 -> 76.737883 | S5: 3 | T5: El Juancho | U5: 2406.5
B6: =PuntosBraacket!A4 -> chatu | C6: =L6*0.15 -> 12.988506 | D6: =Q6*0.85 -> 50.428093 | G6: =C6+D6+E6 -> 63.416599 | H6: 4 | J6: =PuntosBraacket!B4 -> 1582 | L6: =(J6*100/J3) -> 86.590038 | M6: =(J6*100)/$J$4 -> 88.726865 | O6: =PlayerResults!E69 -> 1860.5 | Q6: =(O6*100)/$O$3 -> 59.327168 | S6: 4 | T6: chatu | U6: 1860.5
B7: =PuntosBraacket!A5 -> AND | C7: =L7*0.15 -> 12.422003 | D7: =Q7*0.85 -> 20.457191 | G7: =C7+D7+E7 -> 32.879194 | H7: 5 | J7: =PuntosBraacket!B5 -> 1513 | L7: =(J7*100/J3) -> 82.813355 | M7: =(J7*100)/$J$4 -> 84.856983 | O7: =PlayerResults!F69 -> 754.75 | Q7: =(O7*100)/$O$3 -> 24.067283 | S7: 5 | T7: Dalvila | U7: 1265
B8: =PuntosBraacket!A6 -> Dalvila | C8: =L8*0.15 -> 11.904762 | D8: =Q8*0.85 -> 34.287309 | G8: =C8+D8+E8 -> 46.192071 | H8: 6 | J8: =PuntosBraacket!B6 -> 1450 | L8: =(J8*100/J3) -> 79.365079 | M8: =(J8*100)/$J$4 -> 81.323612 | O8: =PlayerResults!G69 -> 1265 | Q8: =(O8*100)/$O$3 -> 40.33801 | S8: 6 | T8: Narvex | U8: 1209.25
B9: =PuntosBraacket!A7 -> DrWilty | C9: =L9*0.15 -> 11.666667 | D9: =Q9*0.85 -> 31.393893 | G9: =C9+D9+E9 -> 43.06056 | H9: 7 | J9: =PuntosBraacket!B7 -> 1421 | L9: =(J9*100/J3) -> 77.777778 | M9: =(J9*100)/$J$4 -> 79.69714 | O9: =PlayerResults!K69 -> 1158.25 | Q9: =(O9*100)/$O$3 -> 36.933992 | S9: 7 | T9: DrWilty | U9: 1158.25
B10: =PuntosBraacket!A8 -> Narvex | C10: =L10*0.15 -> 11.165846 | D10: =Q10*0.85 -> 32.776228 | G10: =C10+D10+E10 -> 43.942073 | H10: 9 | J10: =PuntosBraacket!B8 -> 1360 | L10: =(J10*100/J3) -> 74.438971 | M10: =(J10*100)/$J$4 -> 76.275939 | O10: =PlayerResults!H69 -> 1209.25 | Q10: =(O10*100)/$O$3 -> 38.560268 | S10: 8 | T10: Mask | U10: 958.75
B11: =PuntosBraacket!A9 -> Saviir | C11: =L11*0.15 -> 10.845649 | D11: =Q11*0.85 -> 25.512197 | G11: =C11+D11+E11 -> 36.357846 | H11: 8 | J11: =PuntosBraacket!B9 -> 1321 | L11: =(J11*100/J3) -> 72.304324 | M11: =(J11*100)/$J$4 -> 74.088615 | O11: =PlayerResults!L69 -> 941.25 | Q11: =(O11*100)/$O$3 -> 30.014349 | S11: 9 | T11: Diexter | U11: 953.5
B12: =PuntosBraacket!A10 -> Diexter | C12: =L12*0.15 -> 10.796388 | D12: =Q12*0.85 -> 25.844228 | G12: =C12+D12+E12 -> 36.640616 | H12: 10 | J12: =PuntosBraacket!B10 -> 1315 | L12: =(J12*100/J3) -> 71.975917 | M12: =(J12*100)/$J$4 -> 73.752103 | O12: =PlayerResults!I69 -> 953.5 | Q12: =(O12*100)/$O$3 -> 30.404974 | S12: 10 | T12: Saviir | U12: 941.25
B13: =PuntosBraacket!A11 -> Mask | C13: =L13*0.15 -> 10.279146 | D13: =Q13*0.85 -> 25.986527 | G13: =C13+D13+E13 -> 36.265674 | H13: 11 | J13: =PuntosBraacket!B11 -> 1252 | L13: =(J13*100/J3) -> 68.527641 | M13: =(J13*100)/$J$4 -> 70.218732 | O13: =PlayerResults!J69 -> 958.75 | Q13: =(O13*100)/$O$3 -> 30.572385 | S13: 11 | T13: Frewe10 | U13: 861.5
B14: =PuntosBraacket!A12 -> Adryx | C14: =L14*0.15 -> 9.8604269 | D14: =Q14*0.85 -> 19.176499 | G14: =C14+D14+E14 -> 29.036926 | H14: 12 | J14: =PuntosBraacket!B12 -> 1201 | L14: =(J14*100/J3) -> 65.73618 | M14: =(J14*100)/$J$4 -> 67.358385 | O14: =PlayerResults!O69 -> 707.5 | Q14: =(O14*100)/$O$3 -> 22.560587 | S14: 12 | T14: AND | U14: 754.75
B15: =PuntosBraacket!A13 -> Rin | C15: =L15*0.15 -> 9.7947455 | D15: =Q15*0.85 -> 11.64481 | G15: =C15+D15+E15 -> 21.439556 | H15: 13 | J15: =PuntosBraacket!B13 -> 1193 | L15: =(J15*100/J3) -> 65.298303 | M15: =(J15*100)/$J$4 -> 66.909703 | O15: =PlayerResults!M69 -> 429.625 | Q15: =(O15*100)/$O$3 -> 13.699777 | S15: 13 | T15: Adryx | U15: 707.5
B16: =PuntosBraacket!A14 -> Nycolast | C16: =L16*0.15 -> 9.5977011 | D16: =Q16*0.85 -> 16.28986 | G16: =C16+D16+E16 -> 25.887561 | H16: 14 | J16: =PuntosBraacket!B14 -> 1169 | L16: =(J16*100/J3) -> 63.984674 | M16: =(J16*100)/$J$4 -> 65.563657 | O16: =PlayerResults!Q69 -> 601 | Q16: =(O16*100)/$O$3 -> 19.164541 | S16: 14 | T16: Nycolast | U16: 601
B17: =PuntosBraacket!A15 -> Gzuto | C17: =L17*0.15 -> 9.3760263 | D17: =Q17*0.85 -> 6.410236 | G17: =C17+D17+E17 -> 15.786262 | H17: 15 | J17: =PuntosBraacket!B15 -> 1142 | L17: =(J17*100/J3) -> 62.506842 | M17: =(J17*100)/$J$4 -> 64.049355 | O17: =PlayerResults!S69 -> 236.5 | Q17: =(O17*100)/$O$3 -> 7.5414541 | S17: 15 | T17: Hanival15 | U17: 459.25
B18: =PuntosBraacket!A16 -> Frewe10 | C18: =L18*0.15 -> 9.2200328 | D18: =Q18*0.85 -> 23.350606 | G18: =C18+D18+E18 -> 32.570639 | H18: 16 | J18: =PuntosBraacket!B16 -> 1123 | L18: =(J18*100/J3) -> 61.466886 | M18: =(J18*100)/$J$4 -> 62.983735 | O18: =PlayerResults!U69 -> 861.5 | Q18: =(O18*100)/$O$3 -> 27.471301 | S18: 16 | T18: Rin | U18: 429.625
B19: =PuntosBraacket!A17 -> EnzoAR | C19: =L19*0.15 -> 9.0147783 | D19: =Q19*0.85 -> 11.55672 | G19: =C19+D19+E19 -> 20.571499 | H19: 17 | J19: =PuntosBraacket!B17 -> 1098 | L19: =(J19*100/J3) -> 60.098522 | M19: =(J19*100)/$J$4 -> 61.581604 | O19: =PlayerResults!R69 -> 426.375 | Q19: =(O19*100)/$O$3 -> 13.596142 | S19: 17 | T19: EnzoAR | U19: 426.375
B20: =PuntosBraacket!A18 -> Sombreitor | C20: =L20*0.15 -> 8.5632184 | D20: =Q20*0.85 -> 11.519452 | G20: =C20+D20+E20 -> 20.08267 | H20: 18 | J20: =PuntosBraacket!B18 -> 1043 | L20: =(J20*100/J3) -> 57.088123 | M20: =(J20*100)/$J$4 -> 58.496915 | O20: =PlayerResults!P69 -> 425 | Q20: =(O20*100)/$O$3 -> 13.552296 | S20: 18 | T20: Sombreitor | U20: 425
B21: =PuntosBraacket!A19 -> Hakko | C21: =L21*0.15 -> 8.0623974 | D21: =Q21*0.85 -> 7.0099251 | G21: =C21+D21+E21 -> 15.072322 | H21: 19 | J21: =PuntosBraacket!B19 -> 982 | L21: =(J21*100/J3) -> 53.749316 | M21: =(J21*100)/$J$4 -> 55.075715 | O21: =PlayerResults!N69 -> 258.625 | Q21: =(O21*100)/$O$3 -> 8.2469707 | S21: 19 | T21: Hakko | U21: 258.625
B22: =PuntosBraacket!A20 -> Hanival15 | C22: =L22*0.15 -> 7.7339901 | D22: =Q22*0.85 -> 12.447784 | G22: =C22+D22+E22 -> 20.181774 | H22: 20 | J22: =PuntosBraacket!B20 -> 942 | L22: =(J22*100/J3) -> 51.559934 | M22: =(J22*100)/$J$4 -> 52.832305 | O22: =PlayerResults!W69 -> 459.25 | Q22: =(O22*100)/$O$3 -> 14.644452 | S22: 20 | T22: Gzuto | U22: 236.5
B23: =PuntosBraacket!A21 -> Traum | C23: =L23*0.15 -> 7.6765189 | D23: =Q23*0.85 -> 1.0943479 | G23: =C23+D23+E23 -> 8.7708668 | H23: 21 | J23: =PuntosBraacket!B21 -> 935 | L23: =(J23*100/J3) -> 51.176793 | M23: =(J23*100)/$J$4 -> 52.439708 | O23: =PlayerResults!V69 -> 40.375 | Q23: =(O23*100)/$O$3 -> 1.2874681 | S23: 21 | T23: Traum | U23: 40.375
B27: Top ordenado actualmente
A28: 1 | B28: Saihara | D28: 100
A29: 2 | B29: Tormen | D29: 88.803691
A30: 3 | B30: El Juancho | D30: 78.929992
A31: 4 | B31: chatu | D31: 63.416599
A32: 5 | B32: Dalvila | D32: 46.192071
A33: 6 | B33: Narvex | D33: 43.942073
A34: 7 | B34: DrWilty | D34: 43.06056
A35: 8 | B35: Diexter | D35: 36.640616
A36: 9 | B36: Saviir | D36: 36.357846
A37: 10 | B37: Mask | D37: 36.265674
A38: 11 | B38: AND | D38: 32.879194
A39: 12 | B39: Frewe10 | D39: 32.570639
... A48: 21 | B48: Traum | D48: 8.7708668

Sheet TorneosScore
A1: Torneo | B1: Score | C1: Entrants
A2: AoT | B2: 1482 | C2: 52 | D2: Tier B | F2: =A2 -> AoT | G2: =B2 -> 1482 | H2: =G2*100/G2 -> 100
A3: CoD5 | B3: 428 | C3: 19 | D3: Tier C | F3: =A3 -> CoD5 | G3: =B3 -> 428 | H3: =G3*100/G2 -> 28.879892
A4: Plátano | B4: 430 | C4: 21 | D4: Tier C | F4: =A4 -> Plátano | G4: =B4 -> 430 | H4: =G4*100/G2 -> 29.014845
A5: CoD6 | B5: 646 | C5: 28 | D5: Tier C | F5: =A5 -> CoD6 | G5: =B5 -> 646 | H5: =G5*100/G2 -> 43.589744
A6: CoD7 | B6: 820 | C6: 37 | D6: Tier B | F6: =A6 -> CoD7 | G6: =B6 -> 820 | H6: =G6*100/G2 -> 55.330634
A7: Caparazón | B7: 694 | C7: 31 | D7: Tier C | F7: =A7 -> Caparazón | G7: =B7 -> 694 | H7: =G7*100/G2 -> 46.82861
A8: CoD8 | B8: 708 | C8: 30 | D8: Tier C | F8: =A8 -> CoD8 | G8: =B8 -> 708 | H8: =G8*100/G2 -> 47.773279
A9: CoD9 | B9: 612 | C9: 24 | D9: Tier C | F9: =A9 -> CoD9 | G9: =B9 -> 612 | H9: =G9*100/G2 -> 41.295547
A10: Hoja | B10: 350 | C10: 16 | D10: Tier C | F10: =A10 -> Hoja | G10: =B10 -> 350 | H10: =G10*100/G2 -> 23.616734
A11: Centella | B11: =(21*14)+50 -> 344 | C11: 14 | D11: Tier D | F11: =A11 -> Centella | G11: =B11 -> 344 | H11: =G11*100/G2 -> 23.211876
A12: CoD10 | B12: 892 | C12: 41 | D12: Tier B | F12: =A12 -> CoD10 | G12: =B12 -> 892 | H12: =G12*100/G2 -> 60.188934
A13: Huevo | B13: 602 | C13: 21 | D13: Tier C | F13: =A13 -> Huevo | G13: =B13 -> 602 | H13: =G13*100/G2 -> 40.620783
A14: CoD11 | B14: 430 | C14: 21 | D14: Tier C | F14: =A14 -> CoD11 | G14: =B14 -> 430 | H14: =G14*100/G2 -> 29.014845
A15: Crossing | B15: 414 | C15: 20 | D15: Tier C | F15: =A15 -> Crossing | G15: =B15 -> 414 | H15: =G15*100/G2 -> 27.935223
A16: CoD12 | B16: 466 | C16: 17 | D16: Tier C | F16: =A16 -> CoD12 | G16: =B16 -> 466 | H16: =G16*100/G2 -> 31.443995
A17: Trifuerza | B17: =(21*12)+20 -> 272 | C17: 12 | D17: Tier D | F17: =A17 -> Trifuerza | G17: =B17 -> 272 | H17: =G17*100/G2 -> 18.353576
A18: CoD13 | B18: 378 | C18: 17 | D18: Tier C | F18: =A18 -> CoD13 | G18: =B18 -> 378 | H18: =G18*100/G2 -> 25.506073
A19: Campana | B19: =(21*10) -> 210 | C19: 10 | D19: Tier D | F19: =A19 -> Campana | G19: =B19 -> 210 | H19: =G19*100/G2 -> 14.17004
A20: PoD:TLS | B20: 822 | C20: 31 | D20: Tier B | F20: =A20 -> PoD:TLS | G20: =B20 -> 822 | H20: =G20*100/G2 -> 55.465587
A24: Neo Sunnyside #8 | B24: 366 | C24: 17 | D24: Joseja (?) | G24: =B24/C24 -> 21.529412 | H24: =21*16 -> 336 | J24: Entre la season 5 SBS y season 6 se incrementó el score de los primeros 48 entrants, haciendo que los torneos pequeños generasen más puntos más rápido
A25: MaraSmash 8 | B25: 446 | C25: 22 | G25: =B25/C25 -> 20.272727 | J25: =350/313 -> 1.1182109
A26: BG Tilts & Taunts 2 (18 sin dqs) | B26: 350 | C26: 16 | D26: Isma (?) | G26: =B26/C26 -> 21.875
A27: Sunnyside Express #21 | B27: 414 | C27: 20 | G27: =B27/C27 -> 20.7
A28: Odin Summer Weekly #55 | B28: 374 | C28: 16 | D28: ZeShi (100), Xiorad (100) | F28: =(B28-B26)/2 -> 12 | G28: =(B28-(F28*2))/C28 -> 21.875 | N28: 19 base | O28: 398
G29: =(G24+G25+G26+G27+G28)/5 -> 21.250428 | N29: 19+top100 | O29: 410
F30: 1 entrant = | G30: 21 supongo? | N30: diff | O30: =O29-O28 -> 12
N32: 1 | O32: =O28/19 -> 20.947368
N33: 16+top30+top100 | O33: 422
N34: 16 base? | O34: =O32*16 -> 335.15789
N35: 16 base real (1a mitad 2023) | O35: 313

Sheet TorneosResults
A1: Torneo | B1: Scores fixed | C1: Entrants | D1: 1 | E1: 2 | F1: 3 | G1: 4 | H1: 5 | I1: 5 | J1: 7 | K1: 7 | L1: 9 | M1: 9 | N1: 9 | O1: 9 | P1: 13 | Q1: 13 | R1: 13 | S1: 13 | T1: 17 | U1: 17 | V1: 17 | W1: 17 | X1: 17 | Y1: 17 | Z1: 17 | AA1: 17 | AB1: 25 | AC1: 25 | AD1: 25 | AE1: 25 | AF1: 25 | AG1: 25 | AH1: 25 | AI1: 25 | AJ1: 33 | AK1: 33 | AL1: 33 | AM1: 33 | AN1: 33 | AO1: 33 | AP1: 33 | AQ1: 33 | AR1: 49
A2: =TorneosScore!A2 -> AoT | B2: =TorneosScore!B2 -> 1482 | C2: =TorneosScore!C2 -> 52 | D2: Scisto | E2: Osoman | F2: Utop-ian | G2: JupiNya | H2: Molo | I2: BlackLoner | J2: gafce | K2: pepe star fox | L2: esca | M2: Dabif | N2: RamonWars | O2: Zant | P2: Lokilla | Q2: Andhi | R2: DjMon | S2: Patrick | T2: Pope | U2: Saihara | V2: chatu | W2: Ego | X2: Fontz | Y2: Golo | Z2: Kuriso | AA2: Tormen | AB2: AND | AC2: angeloti12 | AD2: Ivol | AE2: raishack | AF2: RedKenku | AG2: Jorgito | AH2: AGITO | AI2: Zuka | AJ2: Azfalot | AK2: Dalvila | AL2: Diexter | AM2: El Juancho | AN2: Frewe10 | AO2: Narvex | AP2: Saviir | AQ2: Traum | AR2: Nycolast
A3: =TorneosScore!A3 -> CoD5 | B3: =TorneosScore!B3 -> 428 | C3: =TorneosScore!C3 -> 19 | D3: gafce | E3: El Juancho | F3: Tormen | G3: chatu | H3: Dalvila | I3: Mask | J3: Ch1ris | K3: Narvex | L3: Adryx | M3: Diexter | N3: Foxy | O3: Rin | P3: Hanival15 | Q3: Lonson | R3: Nycolast | S3: Sombreitor | T3: Frewe10 | U3: Leboxi | V3: Soulsilver
A4: =TorneosScore!A4 -> Plátano | B4: =TorneosScore!B4 -> 430 | C4: =TorneosScore!C4 -> 21 | D4: El Juancho | E4: AND | F4: chatu | G4: Zuka | H4: Golo | I4: Narvex | J4: Dalvila | K4: Vemax | L4: Cate | M4: Gzuto | N4: Hakko | O4: Saviir | P4: Ch1ris | Q4: Diexter | R4: EnzoAR | S4: Frewe10 | T4: Nycolast | U4: Ainhi | V4: Eduardo | W4: Foxy | X4: Lonson
A5: =TorneosScore!A5 -> CoD6 | B5: =TorneosScore!B5 -> 646 | C5: =TorneosScore!C5 -> 28 | D5: Molo | E5: Saihara | F5: BlackLoner | G5: El Juancho | H5: Andhi | I5: Frey | J5: chatu | K5: Divain | L5: Ego | M5: Egotzon | N5: Jorgito | O5: Tormen | P5: Dalvila | Q5: Diexter | R5: Narvex | S5: Sombreitor | T5: Adryx | U5: DrWilty | V5: Hanival15 | W5: Jalonso | X5: Mask | Y5: Rin | Z5: Saviir | AA5: Traum | AB5: Edu | AC5: Frewe10 | AD5: Ruben04 | AE5: Soulsilver
A6: =TorneosScore!A6 -> CoD7 | B6: =TorneosScore!B6 -> 820 | C6: =TorneosScore!C6 -> 37 | D6: BlackLoner | E6: Molo | F6: Andhi | G6: Frey | H6: gafce | I6: Saihara | J6: 53845 | K6: El Juancho | L6: AND | M6: Golo | N6: Minix10 | O6: Tormen | P6: Cate | Q6: chatu | R6: Egotzon | S6: Falkko | T6: Dalvila | U6: DaniGetto | V6: Diexter | W6: EnzoAR | X6: Nycolast | Y6: Rin | Z6: Saviir | AA6: Sombreitor | AB6: Adryx | AC6: Cacamot | AD6: Gzuto | AE6: Hanival15 | AF6: Jalonso | AG6: Narvex | AH6: Traum | AI6: aajuñiga | AJ6: Frewe10 | AK6: Dinokami
A7: =TorneosScore!A7 -> Caparazón | B7: =TorneosScore!B7 -> 694 | C7: =TorneosScore!C7 -> 31 | D7: rmoragar | E7: El Juancho | F7: BlackLoner | G7: Saihara | H7: Frey | I7: Tormen | J7: chatu | K7: Golo | L7: AND | M7: Dalvila | N7: Egotzon | O7: Zuka | P7: Default | Q7: Diexter | R7: Mask | S7: Narvex | T7: Cate | U7: ElCope | V7: EnzoAR | W7: Foxy | X7: Frewe10 | Y7: Hakko | Z7: Saviir | AA7: Sombreitor | AB7: ad99 | AC7: Adryx | AD7: Cris284 | AE7: Dinokami | AF7: Edu 024 | AG7: GodT | AH7: Pichuru
A8: =TorneosScore!A8 -> CoD8 | B8: =TorneosScore!B8 -> 708 | C8: =TorneosScore!C8 -> 30 | D8: Molo | E8: BlackLoner | F8: ML41 | G8: Tormen | H8: gafce | I8: Ego | J8: Egotzon | K8: Frey | L8: chatu | M8: Golo | N8: Sabo | O8: Jorgito | P8: Diexter | Q8: DrWilty | R8: El Juancho | S8: Vemax | T8: Dalvila | U8: Edu 024 | V8: Frewe10 | W8: Mask | X8: Narvex | Y8: Rin | Z8: Saviir | AA8: Sombreitor | AB8: Adryx | AC8: Ainhi | AD8: EnzoAR | AE8: Hanival15 | AF8: Nycolast | AG8: Pichuru
A9: =TorneosScore!A9 -> CoD9 | B9: =TorneosScore!B9 -> 612 | C9: =TorneosScore!C9 -> 24 | D9: Molo | E9: Saihara | F9: gafce | G9: ML41 | H9: Ego | I9: Tormen | J9: chatu | K9: Jorgito | L9: Dalvila | M9: DrWilty | N9: Egotzon | O9: Narvex | P9: Adryx | Q9: AngelDust | R9: Diexter | S9: Mask | T9: Edu 024 | U9: EnzoAR | V9: Frewe10 | W9: Kaori | X9: Nycolast | Y9: Pichuru | Z9: Rex suzuki | AA9: Sombreitor
A10: =TorneosScore!A10 -> Hoja | B10: =TorneosScore!B10 -> 350 | C10: =TorneosScore!C10 -> 16 | D10: Tormen | E10: chatu | H10: Mask | I10: Narvex | J10: Diextr79 | K10: Frewe10 | L10: Adryx | M10: Hanival15 | N10: Nycolast | O10: Soulsilver | P10: Dinokami | Q10: Edu 024 | R10: Pichuru | T10: Bafu | Y10: =TorneosScore!A10 -> Hoja
A11: =TorneosScore!A11 -> Centella | B11: =TorneosScore!B11 -> 344 | C11: =TorneosScore!C11 -> 14 | D11: Saihara | E11: Tormen | F11: chatu | G11: Saviir | H11: Diextr79 | I11: Narvex | J11: Gzuto | K11: Nycolast | L11: Adryx | M11: Edu 024 | N11: Frewe10 | Y11: =TorneosScore!A11 -> Centella
A12: =TorneosScore!A12 -> CoD10 | B12: =TorneosScore!B12 -> 892 | C12: =TorneosScore!C12 -> 41 | E12: Saihara | F12: Tormen | H12: chatu | P12: Diextr79 | Q12: Rin | T12: Adryx | U12: Dalvila | V12: DrWilty | W12: Mask | X12: Narvex | Y12: =TorneosScore!A12 -> CoD10
A13: =TorneosScore!A13 -> Huevo | B13: =TorneosScore!B13 -> 602 | C13: =TorneosScore!C13 -> 21 | H13: Tormen | J13: chatu | L13: Dalvila | M13: Diextr79 | N13: Frewe10 | O13: Mask | P13: Narvex | Q13: Nycolast | R13: Rin | S13: Saviir | T13: Adryx | U13: Hakko | V13: Hanival15 | W13: Sombreitor | Y13: =TorneosScore!A13 -> Huevo
A14: =TorneosScore!A14 -> CoD11 | B14: =TorneosScore!B14 -> 430 | C14: =TorneosScore!C14 -> 21 | F14: DrWilty | H14: Dalvila | I14: Saviir | J14: Narvex | L14: Adryx | M14: Diextr79 | N14: EnzoAR | O14: Mask | P14: Frewe10 | Q14: GoldenWind | R14: Hakko | S14: Nycolast | T14: Bafu | U14: Pichuru | V14: Hanival15 | W14: ElBromas05 | X14: Maigar | Y14: =TorneosScore!A14 -> CoD11
A15: =TorneosScore!A15 -> Crossing | B15: =TorneosScore!B15 -> 414 | C15: =TorneosScore!C15 -> 20 | D15: Tormen | H15: Narvex | J15: Diextr79 | L15: Adryx | M15: Mask | N15: Saviir | P15: Frewe10 | Q15: Rex suzuki | R15: Sombreitor | T15: Hanival15 | U15: Hakko | V15: Isa_cty1 | W15: ElBromas05 | Y15: =TorneosScore!A15 -> Crossing
A16: =TorneosScore!A16 -> CoD12 | B16: =TorneosScore!B16 -> 466 | C16: =TorneosScore!C16 -> 17 | F16: DrWilty | G16: Dalvila | H16: Diextr79 | J16: Frewe10 | L16: Adryx | M16: Hanival15 | N16: Narvex | O16: Saviir | P16: GoldenWind | Q16: Pichuru | R16: Sombreitor | T16: Bafu | Y16: =TorneosScore!A16 -> CoD12
A17: =TorneosScore!A17 -> Trifuerza | B17: =TorneosScore!B17 -> 272 | C17: =TorneosScore!C17 -> 12 | D17: Tormen | F17: Narvex | G17: Mask | H17: Dalvila | I17: Nycolast | J17: Hanival15 | K17: Sombreitor | L17: Frewe10 | M17: EnzoAR | N17: ElBromas05 | Y17: =TorneosScore!A17 -> Trifuerza
A18: =TorneosScore!A18 -> CoD13 | B18: =TorneosScore!B18 -> 378 | C18: =TorneosScore!C18 -> 17 | D18: Saihara | F18: El Juancho | G18: Narvex | H18: DrWilty | J18: Adryx | K18: Mask | L18: EnzoAR | M18: Frewe10 | N18: Nycolast | O18: Saviir | P18: Hanival15 | Q18: Sombreitor | R18: GoldenWind | S18: ElBromas05 | T18: Rex suzuki | Y18: =TorneosScore!A18 -> CoD13
A19: =TorneosScore!A19 -> Campana | B19: =TorneosScore!B19 -> 210 | C19: =TorneosScore!C19 -> 10 | D19: Dalvila | E19: Saviir | F19: Narvex | G19: Adryx | H19: Frewe10 | I19: Mask | J19: Nycolast | K19: Sombreitor | L19: Hanival15 | M19: Rex suzuki | Y19: =TorneosScore!A19 -> Campana
A20: =TorneosScore!A20 -> PoD:TLS | B20: =TorneosScore!B20 -> 822 | C20: =TorneosScore!C20 -> 31 | G20: Tormen | H20: Saihara | L20: chatu | M20: Frewe10 | P20: Dalvila | Q20: Saviir | T20: Adryx | U20: Diextr79 | V20: EnzoAR | W20: Narvex | X20: Nycolast | Y20: =TorneosScore!A20 -> PoD:TLS
A29: Método 1
A30: =D30+E30+F30 -> 100 | B30: <8 entrants | C30: =100/3 -> 33.333333 | D30: =C30*1.5 -> 50 | E30: =C30*1 -> 33.333333 | F30: =C30*0.5 -> 16.666667
A31: =D31+E31+F31+G31+H31+J31 -> 100 | B31: <16 entrants | C31: =100/8 -> 12.5 | D31: =C31*2 -> 25 | E31: =C31*1.75 -> 21.875 | F31: =C31*1.5 -> 18.75 | G31: =C31*1.25 -> 15.625 | H31: =C31*1 -> 12.5 | I31: =H31 -> 12.5 | J31: =C31*0.5 -> 6.25 | K31: =J31 -> 6.25
A32: =D32+E32+F32+G32+H32+J32+L32 -> 100 | B32: >=16 entrants | C32: =100/12 -> 8.3333333 | D32: =C32*3 -> 25 | E32: =C32*2.5 -> 20.833333 | F32: =C32*2 -> 16.666667 | G32: =C32*1.5 -> 12.5 | H32: =C32*1.25 -> 10.416667 | I32: =H32 -> 10.416667 | J32: =C32*1 -> 8.3333333 | K32: =J32 -> 8.3333333 | L32: =C32*0.75 -> 6.25 | M32: =L32 -> 6.25 | N32: =L32 -> 6.25 | O32: =L32 -> 6.25
A33: 100 | B33: >=24 entrants | C33: =100/24 -> 4.1666667
B35: Método 2
B36: 100 | C36: <8 entrants | D36: =B36*1 -> 100 | E36: =B36*0.67 -> 67 | F36: =B36*0.33 -> 33
B37: 100 | C37: 8-15 entrants | D37: =B37*1 -> 100 | E37: =B37*0.875 -> 87.5 | F37: =B37*0.75 -> 75 | G37: =B37*0.625 -> 62.5 | H37: =B37*0.5 -> 50 | I37: =H37 -> 50 | J37: =B37*0.375 -> 37.5 | K37: =J37 -> 37.5 | L37: =B37*0.25 -> 25 | M37: =L37 -> 25 | N37: =L37 -> 25 | O37: =L37 -> 25 | P37: =B37*0.125 -> 12.5 | Q37: =P37 -> 12.5 | R37: =P37 -> 12.5 | S37: =P37 -> 12.5 | T37: =B37*0.0625 -> 6.25
B38: 100 | C38: 16-23 entrants | D38: =B38*1 -> 100 | E38: =B38*0.875 -> 87.5 | F38: =B38*0.75 -> 75 | G38: =B38*0.625 -> 62.5 | H38: =B38*0.5 -> 50 | I38: =H38 -> 50 | J38: =B38*0.375 -> 37.5 | K38: =J38 -> 37.5 | L38: =B38*0.25 -> 25 | M38: =L38 -> 25 | N38: =L38 -> 25 | O38: =L38 -> 25 | P38: =B38*0.125 -> 12.5 | Q38: =P38 -> 12.5 | R38: =P38 -> 12.5 | S38: =P38 -> 12.5 | T38: =B38*0.0625 -> 6.25
B39: 100 | C39: 24-32 entrants | D39: =B39*1 -> 100 | E39: =B39*0.875 -> 87.5 | F39: =B39*0.75 -> 75 | G39: =B39*0.625 -> 62.5 | H39: =B39*0.5 -> 50 | I39: =H39 -> 50 | J39: =B39*0.375 -> 37.5 | K39: =J39 -> 37.5 | L39: =B39*0.25 -> 25 | M39: =L39 -> 25 | N39: =L39 -> 25 | O39: =L39 -> 25 | P39: =B39*0.125 -> 12.5 | Q39: =P39 -> 12.5 | R39: =P39 -> 12.5 | S39: =P39 -> 12.5 | T39: =B39*0.0625 -> 6.25
A42: Método 1
A43: =A1 -> Torneo | B43: =C1 -> Entrants | C43: Score/entrant | D43: 1 | E43: 2 | F43: 3 | G43: 4 | H43: 5 | I43: 5 | J43: 7 | K43: 7 | L43: 9 | M43: 9 | N43: 9 | O43: 9 | P43: Score total | Q43: Suma valores
A44: =A2 -> AoT | B44: =C2 -> 52 | C44: =B2/12 -> 123.5 | D44: =C44*3 -> 370.5 | E44: =C44*2.5 -> 308.75 | F44: =C44*2 -> 247 | G44: =C44*1.5 -> 185.25 | H44: =C44*1.25 -> 154.375 | I44: =H44 -> 154.375 | J44: =C44*1 -> 123.5 | K44: =J44 -> 123.5 | L44: =C44*0.75 -> 92.625 | M44: =L44 -> 92.625 | N44: =L44 -> 92.625 | O44: =L44 -> 92.625 | P44: =B2 -> 1482 | Q44: =D44+E44+F44+G44+H44+J44+L44 -> 1482
A45: =A3 -> CoD5 | B45: =C3 -> 19 | C45: =B3/12 -> 35.666667 | D45: =C45*3 -> 107 | E45: =C45*2.5 -> 89.166667 | F45: =C45*2 -> 71.333333 | G45: =C45*1.5 -> 53.5 | H45: =C45*1.25 -> 44.583333 | I45: =H45 -> 44.583333 | J45: =C45*1 -> 35.666667 | K45: =J45 -> 35.666667 | L45: =C45*0.75 -> 26.75 | M45: =L45 -> 26.75 | N45: =L45 -> 26.75 | O45: =L45 -> 26.75 | P45: =B3 -> 428 | Q45: =D45+E45+F45+G45+H45+J45+L45 -> 428
A46: =A4 -> Plátano | B46: =C4 -> 21 | C46: =B4/12 -> 35.833333 | D46: =C46*3 -> 107.5 | E46: =C46*2.5 -> 89.583333 | F46: =C46*2 -> 71.666667 | G46: =C46*1.5 -> 53.75 | H46: =C46*1.25 -> 44.791667 | I46: =H46 -> 44.791667 | J46: =C46*1 -> 35.833333 | K46: =J46 -> 35.833333 | L46: =C46*0.75 -> 26.875 | M46: =L46 -> 26.875 | N46: =L46 -> 26.875 | O46: =L46 -> 26.875 | P46: =B4 -> 430 | Q46: =D46+E46+F46+G46+H46+J46+L46 -> 430
A47: =A5 -> CoD6 | B47: =C5 -> 28 | C47: =B5/12 -> 53.833333 | D47: =C47*3 -> 161.5 | E47: =C47*2.5 -> 134.58333 | F47: =C47*2 -> 107.66667 | G47: =C47*1.5 -> 80.75 | H47: =C47*1.25 -> 67.291667 | I47: =H47 -> 67.291667 | J47: =C47*1 -> 53.833333 | K47: =J47 -> 53.833333 | L47: =C47*0.75 -> 40.375 | M47: =L47 -> 40.375 | N47: =L47 -> 40.375 | O47: =L47 -> 40.375 | P47: =B5 -> 646 | Q47: =D47+E47+F47+G47+H47+J47+L47 -> 646
A48: =A6 -> CoD7 | B48: =C6 -> 37 | C48: =B6/12 -> 68.333333 | D48: =C48*3 -> 205 | E48: =C48*2.5 -> 170.83333 | F48: =C48*2 -> 136.66667 | G48: =C48*1.5 -> 102.5 | H48: =C48*1.25 -> 85.416667 | I48: =H48 -> 85.416667 | J48: =C48*1 -> 68.333333 | K48: =J48 -> 68.333333 | L48: =C48*0.75 -> 51.25 | M48: =L48 -> 51.25 | N48: =L48 -> 51.25 | O48: =L48 -> 51.25 | P48: =B6 -> 820 | Q48: =D48+E48+F48+G48+H48+J48+L48 -> 820
A49: =A7 -> Caparazón | B49: =C7 -> 31 | C49: =B7/12 -> 57.833333 | D49: =C49*3 -> 173.5 | E49: =C49*2.5 -> 144.58333 | F49: =C49*2 -> 115.66667 | G49: =C49*1.5 -> 86.75 | H49: =C49*1.25 -> 72.291667 | I49: =H49 -> 72.291667 | J49: =C49*1 -> 57.833333 | K49: =J49 -> 57.833333 | L49: =C49*0.75 -> 43.375 | M49: =L49 -> 43.375 | N49: =L49 -> 43.375 | O49: =L49 -> 43.375 | P49: =B7 -> 694 | Q49: =D49+E49+F49+G49+H49+J49+L49 -> 694
A50: =A8 -> CoD8 | B50: =C8 -> 30 | C50: =B8/12 -> 59 | D50: =C50*2 -> 118 | E50: =C50*1.75 -> 103.25 | F50: =C50*1.5 -> 88.5 | G50: =C50*1.25 -> 73.75 | H50: =C50*1 -> 59 | I50: =H50 -> 59 | J50: =C50*0.5 -> 29.5 | K50: =J50 -> 29.5 | P50: =B8 -> 708 | Q50: =D50+E50+F50+G50+H50+J50+L50 -> 472
A51: =A9 -> CoD9 | B51: =C9 -> 24 | C51: =B9/12 -> 51 | D51: =C51*3 -> 153 | E51: =C51*2.5 -> 127.5 | F51: =C51*2 -> 102 | G51: =C51*1.5 -> 76.5 | H51: =C51*1.25 -> 63.75 | I51: =H51 -> 63.75 | J51: =C51*1 -> 51 | K51: =J51 -> 51 | L51: =C51*0.75 -> 38.25 | M51: =L51 -> 38.25 | N51: =L51 -> 38.25 | O51: =L51 -> 38.25 | P51: =B9 -> 612 | Q51: =D51+E51+F51+G51+H51+J51+L51 -> 612
...

Sheet PlayerResults
A1: Torneo | B1: Saihara | C1: El Juancho | D1: Tormen | E1: chatu | F1: AND | G1: Dalvila | H1: Narvex | I1: Diexter | J1: Mask | K1: DrWilty | L1: Saviir | M1: Rin | N1: Hakko | O1: Adryx | P1: Sombreitor | Q1: Nycolast | R1: EnzoAR | S1: Gzuto | T1: Jalonso | U1: Frewe10 | V1: Traum | W1: Hanival15
A2: =TorneosScore!A2 -> AoT | B2: 17 | C2: 33 | D2: 17 | E2: 17 | F2: 25 | G2: 33 | H2: 33 | I2: 33 | L2: 33 | Q2: 49 | U2: 33 | V2: 33
A3: =TorneosScore!A3 -> CoD5 | C3: 2 | D3: 3 | E3: 4 | G3: 5 | H3: 7 | I3: 9 | J3: 5 | M3: 9 | O3: 9 | P3: 13 | Q3: 13 | U3: 17 | W3: 13
A4: =TorneosScore!A4 -> Plátano | C4: 1 | E4: 3 | F4: 2 | G4: 7 | H4: 5 | I4: 13 | L4: 9 | N4: 9 | Q4: 17 | R4: 13 | S4: 9 | U4: 13
A5: =TorneosScore!A5 -> CoD6 | B5: 2 | C5: 4 | D5: 9 | E5: 7 | G5: 13 | H5: 13 | I5: 13 | J5: 17 | K5: 17 | L5: 17 | M5: 17 | O5: 17 | P5: 13 | T5: 17 | U5: 25 | V5: 17 | W5: 17
A6: =TorneosScore!A6 -> CoD7 | B6: 5 | C6: 7 | D6: 9 | E6: 13 | F6: 9 | G6: 17 | H6: 25 | I6: 17 | L6: 17 | M6: 17 | O6: 25 | P6: 17 | Q6: 17 | R6: 17 | S6: 25 | T6: 25 | U6: 33 | V6: 25 | W6: 25
A7: =TorneosScore!A7 -> Caparazón | B7: 4 | C7: 2 | D7: 5 | E7: 7 | F7: 9 | G7: 9 | H7: 13 | I7: 13 | J7: 13 | L7: 17 | N7: 17 | O7: 25 | P7: 17 | R7: 17 | U7: 17
A8: =TorneosScore!A8 -> CoD8 | C8: 13 | D8: 4 | E8: 9 | G8: 17 | H8: 17 | I8: 13 | J8: 17 | K8: 13 | L8: 17 | M8: 17 | O8: 25 | P8: 17 | Q8: 25 | R8: 25 | U8: 17 | W8: 25
A9: =TorneosScore!A9 -> CoD9 | B9: 2 | D9: 5 | E9: 7 | G9: 9 | H9: 9 | I9: 13 | J9: 13 | K9: 9 | O9: 13 | P9: 17 | Q9: 17 | R9: 17 | U9: 17
A10: =TorneosScore!A10 -> Hoja | D10: 1 | E10: 2 | H10: 5 | I10: 7 | J10: 5 | O10: 9 | Q10: 9 | U10: 7 | W10: 9
A11: =TorneosScore!A11 -> Centella | B11: 1 | D11: 2 | E11: 3 | H11: 5 | I11: 5 | L11: 4 | O11: 9 | Q11: 7 | S11: 7 | U11: 9
A12: =TorneosScore!A12 -> CoD10 | B12: 2 | D12: 3 | E12: 5 | G12: 17 | H12: 17 | I12: 13 | J12: 17 | K12: 17 | M12: 13 | O12: 17
A13: =TorneosScore!A13 -> Huevo | D13: 5 | E13: 7 | G13: 9 | H13: 13 | I13: 9 | J13: 9 | L13: 13 | M13: 13 | O13: 17 | P13: 17 | Q13: 13 | U13: 9 | W13: 17
A14: =TorneosScore!A14 -> CoD11 | G14: 5 | H14: 7 | I14: 9 | J14: 9 | K14: 3 | L14: 5 | N14: 17 | O14: 9 | Q14: 13 | R14: 9 | U14: 13 | W14: 17
A15: =TorneosScore!A15 -> Crossing | D15: 1 | H15: 5 | I15: 7 | J15: 9 | L15: 9 | N15: 13 | O15: 9 | P15: 13 | U15: 13 | W15: 17
A16: =TorneosScore!A16 -> CoD12 | G16: 4 | H16: 9 | I16: 5 | K16: 3 | L16: 9 | N16: 17 | O16: 9 | P16: 13 | U16: 7 | W16: 9
A17: =TorneosScore!A17 -> Trifuerza | D17: 1 | G17: 5 | H17: 3 | J17: 4 | P17: 7 | Q17: 5 | R17: 9 | U17: 9 | W17: 7
A18: =TorneosScore!A18 -> CoD13 | B18: 1 | C18: 3 | H18: 4 | J18: 7 | K18: 5 | L18: 9 | O18: 7 | P18: 13 | Q18: 9 | R18: 9 | U18: 9 | W18: 13
A19: =TorneosScore!A19 -> Campana | G19: 1 | H19: 3 | J19: 5 | L19: 2 | O19: 4 | P19: 7 | Q19: 7 | U19: 5 | W19: 9
A20: =TorneosScore!A20 -> PoD:TLS | B20: 5 | D20: 4 | E20: 9 | G20: 13 | H20: 17 | I20: 17 | L20: 13 | O20: 17 | Q20: 17 | R20: 17 | U20: 9
A25: Score | B25: Saihara | C25: El Juancho | D25: Tormen | E25: chatu | F25: AND | G25: Dalvila | H25: Narvex | I25: Diexter | J25: Mask | K25: DrWilty | L25: Saviir | M25: Rin | N25: Hakko | O25: Adryx | P25: Sombreitor | Q25: Nycolast | R25: EnzoAR | S25: Gzuto | T25: Jalonso | U25: Frewe10 | V25: Traum | W25: Hanival15
A26: =TorneosScore!A2 -> AoT | B26: =TorneosResults!L55 -> 92.625 | C26: 0 | D26: =TorneosResults!L55 -> 92.625 | E26: =TorneosResults!L55 -> 92.625 | F26: 0 | G26: 0 | H26: 0 | I26: 0 | L26: 0 | Q26: 0 | U26: 0 | V26: 0
A27: =TorneosScore!A3 -> CoD5 | C27: =TorneosResults!E56 -> 374.5 | D27: =TorneosResults!F56 -> 321 | E27: =TorneosResults!G56 -> 267.5 | G27: =TorneosResults!H56 -> 214 | H27: =TorneosResults!I56 -> 160.5 | I27: =TorneosResults!J56 -> 107 | J27: =TorneosResults!H56 -> 214 | M27: =TorneosResults!J56 -> 107 | O27: =TorneosResults!J56 -> 107 | P27: =TorneosResults!K56 -> 53.5 | Q27: =TorneosResults!K56 -> 53.5 | U27: =TorneosResults!L56 -> 26.75 | W27: =TorneosResults!K56 -> 53.5
A28: =TorneosScore!A4 -> Plátano | C28: =TorneosResults!D57 -> 430 | E28: =TorneosResults!F57 -> 322.5 | F28: =TorneosResults!E57 -> 376.25 | G28: =TorneosResults!I57 -> 161.25 | H28: =TorneosResults!H57 -> 215 | I28: =TorneosResults!K57 -> 53.75 | L28: =TorneosResults!J57 -> 107.5 | N28: =TorneosResults!J57 -> 107.5 | Q28: =TorneosResults!L57 -> 26.875 | R28: =TorneosResults!K57 -> 53.75 | S28: =TorneosResults!J57 -> 107.5 | U28: =TorneosResults!K57 -> 53.75
A29: =TorneosScore!A5 -> CoD6 | B29: =TorneosResults!E58 -> 565.25 | C29: =TorneosResults!G58 -> 403.75 | D29: =TorneosResults!J58 -> 161.5 | E29: =TorneosResults!I58 -> 242.25 | G29: =TorneosResults!K58 -> 80.75 | H29: =TorneosResults!K58 -> 80.75 | I29: =TorneosResults!K58 -> 80.75 | J29: =TorneosResults!L58 -> 40.375 | K29: =TorneosResults!L58 -> 40.375 | L29: =TorneosResults!L58 -> 40.375 | M29: =TorneosResults!L58 -> 40.375 | O29: =TorneosResults!L58 -> 40.375 | P29: =TorneosResults!K58 -> 80.75 | T29: =TorneosResults!L58 -> 40.375 | U29: 0 | V29: =TorneosResults!L58 -> 40.375 | W29: =TorneosResults!L58 -> 40.375
A30: =TorneosScore!A6 -> CoD7 | B30: =TorneosResults!H59 -> 410 | C30: =TorneosResults!I59 -> 307.5 | D30: =TorneosResults!J59 -> 205 | E30: =TorneosResults!K59 -> 102.5 | F30: =TorneosResults!J59 -> 205 | G30: =TorneosResults!L59 -> 51.25 | H30: 0 | I30: =TorneosResults!L59 -> 51.25 | L30: =TorneosResults!L59 -> 51.25 | M30: =TorneosResults!L59 -> 51.25 | O30: 0 | P30: =TorneosResults!L59 -> 51.25 | Q30: =TorneosResults!L59 -> 51.25 | R30: =TorneosResults!L59 -> 51.25 | S30: 0 | T30: 0 | U30: 0 | V30: 0 | W30: 0
A31: =TorneosScore!A7 -> Caparazón | B31: =TorneosResults!G60 -> 433.75 | C31: =TorneosResults!E60 -> 607.25 | D31: =TorneosResults!H60 -> 347 | E31: =TorneosResults!I60 -> 260.25 | F31: =TorneosResults!J60 -> 173.5 | G31: =TorneosResults!J60 -> 173.5 | H31: =TorneosResults!K60 -> 86.75 | I31: =TorneosResults!K60 -> 86.75 | J31: =TorneosResults!K60 -> 86.75 | L31: =TorneosResults!L60 -> 43.375 | N31: =TorneosResults!L60 -> 43.375 | O31: 0 | P31: =TorneosResults!L60 -> 43.375 | R31: =TorneosResults!L60 -> 43.375 | U31: =TorneosResults!L60 -> 43.375
A32: =TorneosScore!A8 -> CoD8 | C32: =TorneosResults!K61 -> 88.5 | D32: =TorneosResults!G61 -> 442.5 | E32: =TorneosResults!J61 -> 177 | G32: =TorneosResults!L61 -> 44.25 | H32: =TorneosResults!L61 -> 44.25 | I32: =TorneosResults!K61 -> 88.5 | J32: =TorneosResults!L61 -> 44.25 | K32: =TorneosResults!K61 -> 88.5 | L32: =TorneosResults!L61 -> 44.25 | M32: =TorneosResults!L61 -> 44.25 | O32: 0 | P32: =TorneosResults!L61 -> 44.25 | Q32: 0 | R32: 0 | U32: =TorneosResults!L61 -> 44.25 | W32: 0
A33: =TorneosScore!A9 -> CoD9 | B33: =TorneosResults!E62 -> 535.5 | D33: =TorneosResults!H62 -> 306 | E33: =TorneosResults!I62 -> 229.5 | G33: =TorneosResults!J62 -> 153 | H33: =TorneosResults!J62 -> 153 | I33: =TorneosResults!K62 -> 76.5 | J33: =TorneosResults!K62 -> 76.5 | K33: =TorneosResults!J62 -> 153 | O33: =TorneosResults!K62 -> 76.5 | P33: =TorneosResults!L62 -> 38.25 | Q33: =TorneosResults!L62 -> 38.25 | R33: =TorneosResults!L62 -> 38.25 | U33: =TorneosResults!L62 -> 38.25
A34: =TorneosScore!A10 -> Hoja | D34: =TorneosResults!D63 -> 350 | E34: =TorneosResults!E63 -> 306.25 | H34: =TorneosResults!H63 -> 175 | I34: =TorneosResults!I63 -> 131.25 | J34: =TorneosResults!H63 -> 175 | O34: =TorneosResults!J63 -> 87.5 | Q34: =TorneosResults!J63 -> 87.5 | U34: =TorneosResults!I63 -> 131.25 | W34: =TorneosResults!J63 -> 87.5
A35: =TorneosScore!A11 -> Centella | B35: =TorneosResults!D64 -> 344 | D35: =TorneosResults!E64 -> 301 | E35: =TorneosResults!F64 -> 258 | H35: =TorneosResults!H64 -> 172 | I35: =TorneosResults!H64 -> 172 | L35: =TorneosResults!G64 -> 215 | O35: =TorneosResults!J64 -> 86 | Q35: =TorneosResults!I64 -> 129 | S35: =TorneosResults!I64 -> 129 | U35: =TorneosResults!J64 -> 86
A36: =TorneosScore!A12 -> CoD10 | B36: =TorneosResults!E65 -> 780.5 | D36: =TorneosResults!F65 -> 669 | E36: =TorneosResults!H65 -> 446 | G36: =TorneosResults!L65 -> 55.75 | H36: =TorneosResults!L65 -> 55.75 | I36: =TorneosResults!K65 -> 111.5 | J36: =TorneosResults!L65 -> 55.75 | K36: =TorneosResults!L65 -> 55.75 | M36: =TorneosResults!K65 -> 111.5 | O36: =TorneosResults!L65 -> 55.75
A37: =TorneosScore!A13 -> Huevo | D37: =TorneosResults!H66 -> 301 | E37: =TorneosResults!I66 -> 225.75 | G37: =TorneosResults!J66 -> 150.5 | H37: =TorneosResults!K66 -> 75.25 | I37: =TorneosResults!J66 -> 150.5 | J37: =TorneosResults!J66 -> 150.5 | L37: =TorneosResults!K66 -> 75.25 | M37: =TorneosResults!K66 -> 75.25 | O37: =TorneosResults!L66 -> 37.625 | P37: =TorneosResults!L66 -> 37.625 | Q37: =TorneosResults!K66 -> 75.25 | U37: =TorneosResults!J66 -> 150.5 | W37: =TorneosResults!L66 -> 37.625
A38: =TorneosScore!A14 -> CoD11 | G38: =TorneosResults!H67 -> 215 | H38: =TorneosResults!I67 -> 161.25 | I38: =TorneosResults!J67 -> 107.5 | J38: =TorneosResults!J67 -> 107.5 | K38: =TorneosResults!F67 -> 322.5 | L38: =TorneosResults!H67 -> 215 | N38: =TorneosResults!L67 -> 26.875 | O38: =TorneosResults!J67 -> 107.5 | Q38: =TorneosResults!K67 -> 53.75 | R38: =TorneosResults!J67 -> 107.5 | U38: =TorneosResults!K67 -> 53.75 | W38: =TorneosResults!L67 -> 26.875
A39: =TorneosScore!A15 -> Crossing | D39: =TorneosResults!D68 -> 414 | H39: =TorneosResults!H68 -> 207 | I39: =TorneosResults!I68 -> 155.25 | J39: =TorneosResults!J68 -> 103.5 | L39: =TorneosResults!J68 -> 103.5 | N39: =TorneosResults!K68 -> 51.75 | O39: =TorneosResults!J68 -> 103.5 | P39: =TorneosResults!K68 -> 51.75 | U39: =TorneosResults!K68 -> 51.75 | W39: =TorneosResults!L68 -> 25.875
A40: =TorneosScore!A16 -> CoD12 | G40: =TorneosResults!G69 -> 291.25 | H40: =TorneosResults!J69 -> 116.5 | I40: =TorneosResults!H69 -> 233 | K40: =TorneosResults!F69 -> 349.5 | L40: =TorneosResults!J69 -> 116.5 | N40: =TorneosResults!L69 -> 29.125 | O40: =TorneosResults!J69 -> 116.5 | P40: =TorneosResults!K69 -> 58.25 | U40: =TorneosResults!I69 -> 174.75 | W40: =TorneosResults!J69 -> 116.5
A41: =TorneosScore!A17 -> Trifuerza | D41: =TorneosResults!D70 -> 272 | G41: =TorneosResults!H70 -> 136 | H41: =TorneosResults!F70 -> 204 | J41: =TorneosResults!G70 -> 170 | P41: =TorneosResults!I70 -> 102 | Q41: =TorneosResults!H70 -> 136 | R41: =TorneosResults!J70 -> 68 | U41: =TorneosResults!J70 -> 68 | W41: =TorneosResults!I70 -> 102
A42: =TorneosScore!A18 -> CoD13 | B42: =TorneosResults!D71 -> 378 | C42: =TorneosResults!F71 -> 283.5 | H42: =TorneosResults!G71 -> 236.25 | J42: =TorneosResults!I71 -> 141.75 | K42: =TorneosResults!H71 -> 189 | L42: =TorneosResults!J71 -> 94.5 | O42: =TorneosResults!I71 -> 141.75 | P42: =TorneosResults!K71 -> 47.25 | Q42: =TorneosResults!J71 -> 94.5 | R42: =TorneosResults!J71 -> 94.5 | U42: =TorneosResults!J71 -> 94.5 | W42: =TorneosResults!K71 -> 47.25
A43: =TorneosScore!A19 -> Campana | G43: =TorneosResults!D72 -> 210 | H43: =TorneosResults!F72 -> 157.5 | J43: =TorneosResults!H72 -> 105 | L43: =TorneosResults!E72 -> 183.75 | O43: =TorneosResults!G72 -> 131.25 | P43: =TorneosResults!I72 -> 78.75 | Q43: =TorneosResults!I72 -> 78.75 | U43: =TorneosResults!H72 -> 105 | W43: =TorneosResults!J72 -> 52.5
A44: =TorneosScore!A20 -> PoD:TLS | B44: =TorneosResults!H73 -> 411 | D44: =TorneosResults!G73 -> 513.75 | E44: =TorneosResults!J73 -> 205.5 | G44: =TorneosResults!K73 -> 102.75 | H44: =TorneosResults!L73 -> 51.375 | I44: =TorneosResults!L73 -> 51.375 | L44: =TorneosResults!K73 -> 102.75 | O44: =TorneosResults!L73 -> 51.375 | Q44: =TorneosResults!L73 -> 51.375 | R44: =TorneosResults!L73 -> 51.375 | U44: =TorneosResults!J73 -> 205.5
...

Sheet PuntosBraacket
A1: Saihara | B1: 1827 | D1: >9 Asistencia | F1: Extranjeros >9 | H1: Extranjeros >5
A2: Tormen | B2: 1783 | D2: Saihara | F2: Molo | H2: BlackLoner
A3: El Juancho | B3: 1669 | D3: Tormen | F3: JorgitoPredator | H3: gafce
A4: chatu | B4: 1582 | D4: El Juancho | F4: Golo | H4: Ego
A5: AND | B5: 1513 | D5: chatu | H5: ANGEL DUST
A6: Dalvila | B6: 1450 | D6: Dalvila | H6: Egotzon
A7: DrWilty | B7: 1421 | D7: DrWilty | H7: Zuka
A8: Narvex | B8: 1360 | D8: Narvex | H8: Ainhi
A9: Saviir | B9: 1321 | D9: Saviir
A10: Diexter | B10: 1315 | D10: Diexter
A11: Mask | B11: 1252 | D11: Mask
A12: Adryx | B12: 1201 | D12: Adryx
A13: Rin | B13: 1193 | D13: Nycolast
A14: Nycolast | B14: 1169 | D14: Frewe10
A15: Gzuto | B15: 1142 | D15: EnzoAR
A16: Frewe10 | B16: 1123 | D16: Sombreitor
A17: EnzoAR | B17: 1098 | D17: Hanival15
A18: Sombreitor | B18: 1043
A19: Hakko | B19: 982
A20: Hanival15 | B20: 942
A21: Traum | B21: 935
