Workbook

Sheet Ranking
B2: Player | C2: H2H (10%) | D2: Results (80%) | E2: Torneo final (10%) | G2: Total | J2: Raw H2H Score | L2: Fixed H2H Score | O2: Raw Results Score | Q2: Fixed Results Score
B3: Saihara | C3: =L3*0.1 -> 10 | D3: =Q3*0.8 -> 78.917929 | G3: =C3+D3+E3 -> 88.917929 | H3: 0 | J3: =PuntosBraacket!B1 -> 6504 | L3: =(J3*100/J3) -> 100 | O3: =PlayerResults!B49 -> 404.16667 | Q3: =(O3*100)/$O$4 -> 98.647412
A4: =L4*0.1 -> 9.1805043 | B4: El Juancho | C4: =M4*0.1 -> 10 | D4: =Q4*0.8 -> 80 | G4: =C4+D4+E4 -> 90 | H4: 1 | J4: =PuntosBraacket!B2 -> 5971 | L4: =(J4*100/J3) -> 91.805043 | M4: =(J4*100)/$J$4 -> 100 | O4: =PlayerResults!C49 -> 409.70833 | Q4: =(O4*100)/$O$4 -> 100
B5: Slogan | C5: =M5*0.1 -> 9.2078379 | D5: =Q5*0.8 -> 65.021865 | G5: =C5+D5+E5 -> 74.229703 | H5: ? | J5: =PuntosBraacket!B3 -> 5498 | L5: =(J5*100/J3) -> 84.532595 | M5: =(J5*100)/$J$4 -> 92.078379 | O5: =PlayerResults!D49 -> 333 | Q5: =(O5*100)/$O$4 -> 81.277331
B6: Tormen | C6: =M6*0.1 -> 8.8377156 | D6: =Q6*0.8 -> 48.416556 | G6: =C6+D6+E6 -> 57.254272 | H6: 3 | J6: =PuntosBraacket!B4 -> 5277 | L6: =(J6*100/J3) -> 81.134686 | M6: =(J6*100)/$J$4 -> 88.377156 | O6: =PlayerResults!E49 -> 247.95833 | Q6: =(O6*100)/$O$4 -> 60.520696
B7: chatu | C7: =M7*0.1 -> 8.6752638 | D7: =Q7*0.8 -> 62.058375 | G7: =C7+D7+E7 -> 70.733639 | H7: 2 | J7: =PuntosBraacket!B5 -> 5180 | L7: =(J7*100/J3) -> 79.643296 | M7: =(J7*100)/$J$4 -> 86.752638 | O7: =PlayerResults!F49 -> 317.82292 | Q7: =(O7*100)/$O$4 -> 77.572969
B8: AND | C8: =M8*0.1 -> 7.8127617 | D8: =Q8*0.8 -> 46.504627 | G8: =C8+D8+E8 -> 54.317389 | H8: 4 | J8: =PuntosBraacket!B6 -> 4665 | L8: =(J8*100/J3) -> 71.725092 | M8: =(J8*100)/$J$4 -> 78.127617 | O8: =PlayerResults!G49 -> 238.16667 | Q8: =(O8*100)/$O$4 -> 58.130784
B9: DrWilty | C9: =M9*0.1 -> 7.0708424 | D9: =Q9*0.8 -> 41.24072 | G9: =C9+D9+E9 -> 48.311562 | H9: 5 | J9: =PuntosBraacket!B7 -> 4222 | L9: =(J9*100/J3) -> 64.913899 | M9: =(J9*100)/$J$4 -> 70.708424 | O9: =PlayerResults!H49 -> 211.20833 | Q9: =(O9*100)/$O$4 -> 51.5509
B10: Lego | C10: =M10*0.1 -> 6.9619829 | D10: =Q10*0.8 -> 20.038645 | G10: =C10+D10+E10 -> 27.000628 | H10: 9 | J10: =PuntosBraacket!B8 -> 4157 | L10: =(J10*100/J3) -> 63.914514 | M10: =(J10*100)/$J$4 -> 69.619829 | O10: =PlayerResults!I49 -> 102.625 | Q10: =(O10*100)/$O$4 -> 25.048307
B11: Azfalot | C11: =M11*0.1 -> 6.1380003 | D11: =Q11*0.8 -> 26.80362 | G11: =C11+D11+E11 -> 32.941621 | H11: 8 | J11: =PuntosBraacket!B9 -> 3665 | L11: =(J11*100/J3) -> 56.349938 | M11: =(J11*100)/$J$4 -> 61.380003 | O11: =PlayerResults!J49 -> 137.27083 | Q11: =(O11*100)/$O$4 -> 33.504526
B12: Dalvila | C12: =M12*0.1 -> 6.020767 | D12: =Q12*0.8 -> 35.736805 | G12: =C12+D12+E12 -> 41.757572 | H12: 6 | J12: =PuntosBraacket!B10 -> 3595 | L12: =(J12*100/J3) -> 55.273678 | M12: =(J12*100)/$J$4 -> 60.20767 | O12: =PlayerResults!K49 -> 183.02083 | Q12: =(O12*100)/$O$4 -> 44.671006
B13: Narvex | C13: =M13*0.1 -> 4.6424385 | D13: =Q13*0.8 -> 27.600936 | G13: =C13+D13+E13 -> 32.243374 | H13: 7 | J13: =PuntosBraacket!B11 -> 2772 | L13: =(J13*100/J3) -> 42.619926 | M13: =(J13*100)/$J$4 -> 46.424385 | O13: =PlayerResults!L49 -> 141.35417 | Q13: =(O13*100)/$O$4 -> 34.50117
B14: Diextr79 | C14: =M14*0.1 -> 4.4163457 | D14: =Q14*0.8 -> 16.629716 | G14: =C14+D14+E14 -> 21.046062 | H14: 10 | J14: =PuntosBraacket!B12 -> 2637 | L14: =(J14*100/J3) -> 40.54428 | M14: =(J14*100)/$J$4 -> 44.163457 | O14: =PlayerResults!M49 -> 85.166667 | Q14: =(O14*100)/$O$4 -> 20.787145
B15: Mask | C15: =M15*0.1 -> 4.3694524 | D15: =Q15*0.8 -> 9.68982 | G15: =C15+D15+E15 -> 14.059272 | H15: 12 | J15: =PuntosBraacket!B13 -> 2609 | L15: =(J15*100/J3) -> 40.113776 | M15: =(J15*100)/$J$4 -> 43.694524 | O15: =PlayerResults!N49 -> 49.625 | Q15: =(O15*100)/$O$4 -> 12.112275
B16: Rin | C16: =M16*0.1 -> 3.7514654 | D16: =Q16*0.8 -> 14.27845 | G16: =C16+D16+E16 -> 18.029916 | H16: 11 | J16: =PuntosBraacket!B14 -> 2240 | L16: =(J16*100/J3) -> 34.440344 | M16: =(J16*100)/$J$4 -> 37.514654 | O16: =PlayerResults!O49 -> 73.125 | Q16: =(O16*100)/$O$4 -> 17.848063
B17: Saviir | C17: =M17*0.1 -> 3.6392564 | D17: =Q17*0.8 -> 9.68982 | G17: =C17+D17+E17 -> 13.329076 | H17: 13 | J17: =PuntosBraacket!B15 -> 2173 | L17: =(J17*100/J3) -> 33.410209 | M17: =(J17*100)/$J$4 -> 36.392564 | O17: =PlayerResults!P49 -> 49.625 | Q17: =(O17*100)/$O$4 -> 12.112275
B18: AlvaGames99 | C18: =M18*0.1 -> 3.2205661 | D18: =Q18*0.8 -> 8.7704668 | G18: =C18+D18+E18 -> 11.991033 | H18: 15 | J18: =PuntosBraacket!B16 -> 1923 | L18: =(J18*100/J3) -> 29.566421 | M18: =(J18*100)/$J$4 -> 32.205661 | O18: =PlayerResults!Q49 -> 44.916667 | Q18: =(O18*100)/$O$4 -> 10.963083
B19: Traum | C19: =M19*0.1 -> 3.0731871 | D19: =Q19*0.8 -> 10.153565 | G19: =C19+D19+E19 -> 13.226752 | H19: 14 | J19: =PuntosBraacket!B17 -> 1835 | L19: =(J19*100/J3) -> 28.213407 | M19: =(J19*100)/$J$4 -> 30.731871 | O19: =PlayerResults!R49 -> 52 | Q19: =(O19*100)/$O$4 -> 12.691956
B20: Frewe10 | C20: =M20*0.1 -> 2.5188411 | D20: =Q20*0.8 -> 4.8327062 | G20: =C20+D20+E20 -> 7.3515473 | H20: 17 | J20: =PuntosBraacket!B18 -> 1504 | L20: =(J20*100/J3) -> 23.124231 | M20: =(J20*100)/$J$4 -> 25.188411 | O20: =PlayerResults!S49 -> 24.75 | Q20: =(O20*100)/$O$4 -> 6.0408827
B21: Foxy | C21: =M21*0.1 -> 2.3530397 | D21: =Q21*0.8 -> 4.2713312 | G21: =C21+D21+E21 -> 6.6243709 | H21: 18 | J21: =PuntosBraacket!B19 -> 1405 | L21: =(J21*100/J3) -> 21.602091 | M21: =(J21*100)/$J$4 -> 23.530397 | O21: =PlayerResults!T49 -> 21.875 | Q21: =(O21*100)/$O$4 -> 5.339164
B22: Dinokami | C22: =M22*0.1 -> 1.361581 | D22: =Q22*0.8 -> 0 | G22: =C22+D22+E22 -> 1.361581 | H22: 19 | J22: =PuntosBraacket!B20 -> 813 | L22: =(J22*100/J3) -> 12.5 | M22: =(J22*100)/$J$4 -> 13.61581 | O22: =PlayerResults!U49 -> 0 | Q22: =(O22*100)/$O$4 -> 0
B23: Ing3nio | C23: =M23*0.1 -> 0.10718473 | D23: =Q23*0.8 -> 0 | G23: =C23+D23+E23 -> 0.10718473 | H23: 20 | J23: =PuntosBraacket!B21 -> 64 | L23: =(J23*100/J3) -> 0.98400984 | M23: =(J23*100)/$J$4 -> 1.0718473 | O23: =PlayerResults!V49 -> 0 | Q23: =(O23*100)/$O$4 -> 0
B24: Leboxi | C24: =M24*0.1 -> 0 | D24: =Q24*0.8 -> 0 | G24: =C24+D24+E24 -> 0 | H24: 21 | J24: =PuntosBraacket!B22 -> 0 | L24: =(J24*100/J3) -> 0 | M24: =(J24*100)/$J$4 -> 0 | O24: =PlayerResults!W49 -> 0 | Q24: =(O24*100)/$O$4 -> 0
B25: Tora | C25: =M25*0.1 -> 4.6273656 | D25: =Q25*0.8 -> 7.1188854 | G25: =C25+D25+E25 -> 11.746251 | H25: 16 | J25: =PuntosBraacket!B23 -> 2763 | L25: =(J25*100/J4) -> 46.273656 | M25: =(J25*100)/$J$4 -> 46.273656 | O25: =PlayerResults!X49 -> 36.458333 | Q25: =(O25*100)/$O$4 -> 8.8986067
B27: Top ordenado actualmente
A28: 0 | B28: Saihara | D28: =G3 -> 88.917929 | F28: Encuesta WhatsApp | I28: V | J28: D
A29: 1 | B29: El Juancho | D29: =G4 -> 90 | F29: El Juancho | G29: V,D | I29: Juancho | J29: Juancho
A30: 2 | B30: chatu | D30: =G7 -> 70.733639 | F30: chatu | G30: V,D | I30: chatu | J30: chatu
A31: 3 | B31: Tormen | D31: =G6 -> 57.254272 | F31: Tormen | G31: V,D,J | I31: Tormen | J31: Tormen
A32: 4 | B32: AND | D32: =G8 -> 54.317389 | F32: AND | J32: Wilty
A33: 5 | B33: DrWilty | D33: =G9 -> 48.311562 | F33: DrWilty | G33: D,J | I33: Dalvila | J33: Dalvila
A34: 6 | B34: Dalvila | D34: =G12 -> 41.757572 | F34: Dalvila | G34: V,D,J | J34: Narvex
A35: 7 | B35: Azfalot | D35: =G11 -> 32.941621 | F35: Narvex | G35: D,J | I35: Diextr | J35: Diextr
A36: 8 | B36: Narvex | D36: =G13 -> 32.243374 | F36: Azfalot | I36: Rin | J36: Rin
A37: 9 | B37: Lego | D37: =G10 -> 27.000628 | F37: Lego | I37: Mask | J37: Mask
A38: 10 | B38: Diextr79 | D38: =G14 -> 21.046062 | F38: Diextr79 | G38: V,D,J | I38: Saviir | J38: Saviir
A39: 11 | B39: Rin | D39: =G16 -> 18.029916 | F39: Rin | G39: V,D | J39: Traum
A40: 12 | B40: Mask | D40: =G15 -> 14.059272 | F40: Mask | G40: V,D | I40: Frewe | J40: Frewe
A41: 13 | B41: Saviir | D41: =G17 -> 13.329076 | F41: Saviir | G41: V,D
A42: 14 | B42: Traum | D42: =G19 -> 13.226752 | F42: Traum | G42: D
...

Sheet TorneosScore
A1: Torneo | B1: Score | C1: Entrants
A2: CoD4 | B2: 422 | C2: 16 | G2: 19 base | H2: 398
A3: Corona | B3: 398 | C3: 19 | G3: 19+top100 | H3: 410
A4: CoD3 | B4: 596 | C4: 25 | G4: diff | H4: =H3-H2 -> 12
A5: Estrella | B5: 410 | C5: 19
A6: CoD2 | B6: ? | C6: 15 | D6: Molo (30), Ramon (50), gafce (100) | G6: 1 | H6: =H2/19 -> 20.947368 | J6: =(21*C6)+12+30+65 -> 422 | K6: Contar este como tier C (>16 entrants) al dividir score por la burrada de puntos que tiene
A7: Flor | B7: 366 | C7: 17 | G7: 16+top30+top100 | H7: 422
A8: CoD1 | B8: ? | C8: 11 | G8: 16 base? | H8: =H6*16 -> 335.15789 | J8: =(21*C8) -> 231
A9: Champiñón | B9: 396 | C9: 17 | G9: 16 base real (1a mitad 2023) | H9: 313 | K9: Multiplicador season 6
A10: TBO17 | B10: ? | C10: 12 | D10: Saihara (?) | G10: 1 real? | H10: =H9/16 -> 19.5625 | J10: =(21*C10) -> 252 | L10: Redondeo
A11: TBO16 | B11: 348 | C11: 18 | H11: =H10*20 -> 391.25 | K11: =B11*$J$22 -> 389.13738 | L11: 389
A12: TBO15 | B12: 411 | C12: 20 | H12: =H6*19 -> 398 | K12: =B12*$J$22 -> 459.58466 | L12: 460
A13: CR4 | B13: ? | C13: 4 | J13: =(21*C13) -> 84
A14: CR3 | B14: ? | C14: 5 | J14: =(21*C14) -> 105
A15: TBO14 | B15: 313 | C15: 16 | K15: =B15*$J$22 -> 350 | L15: 350
A16: CR2 | B16: ? | C16: 7 | J16: =(21*C16) -> 147
A17: CR1 | B17: ? | C17: 5 | J17: =(21*C17) -> 105
A18: TBO13 | B18: 378 | C18: 18 | K18: =B18*$J$22 -> 422.68371 | L18: 423
A19: TBO12 | B19: ? | C19: 7 | D19: Saihara (?) | J19: =(21*C19) -> 147
A21: Neo Sunnyside #8 | B21: 366 | C21: 17 | D21: Joseja (?) | G21: =B21/C21 -> 21.529412 | H21: =21*16 -> 336 | J21: Entre la season 5 SBS y season 6 se incrementó el score de los primeros 48 entrants, haciendo que los torneos pequeños generasen más puntos más rápido
A22: MaraSmash 8 | B22: 446 | C22: 22 | G22: =B22/C22 -> 20.272727 | J22: =350/313 -> 1.1182109
A23: BG Tilts & Taunts 2 (18 sin dqs) | B23: 350 | C23: 16 | D23: Isma (?) | G23: =B23/C23 -> 21.875
A24: Sunnyside Express #21 | B24: 414 | C24: 20 | G24: =B24/C24 -> 20.7
A25: Odin Summer Weekly #55 | B25: 374 | C25: 16 | D25: ZeShi (100), Xiorad (100) | F25: =(B25-B23)/2 -> 12 | G25: =(B25-(F25*2))/C25 -> 21.875
G26: =(G21+G22+G23+G24+G25)/5 -> 21.250428
F27: 1 entrant = | G27: 21 supongo?

Sheet TorneosResults
A1: Torneo | B1: Scores fixed | C1: Entrants | D1: 1 | E1: 2 | F1: 3 | G1: 4 | H1: 5 | I1: 5 | J1: 7 | K1: 7 | L1: 9 | M1: 9 | N1: 9 | O1: 9 | P1: 13 | Q1: 13 | R1: 13 | S1: 13 | T1: 17 | U1: 17 | V1: 17 | W1: 17 | X1: 17 | Y1: 17 | Z1: 17 | AA1: 17 | AB1: 25 | AC1: 25
A2: =TorneosScore!A2 -> CoD4 | B2: =TorneosScore!B2 -> 422 | C2: =TorneosScore!C2 -> 16 | D2: molo | E2: gafce | F2: juancho | G2: andhi | H2: chatu | I2: tormen | J2: aitorx24 | K2: and | L2: wilty | M2: egotzon | N2: rin | O2: traum | P2: diextr | Q2: ing3nio | R2: narvex | S2: saviir
A3: =TorneosScore!A3 -> Corona | B3: =TorneosScore!B3 -> 398 | C3: =TorneosScore!C3 -> 19 | D3: saihara | E3: juancho | F3: and | G3: chatu | H3: dalvila | I3: tormen | J3: diextr | K3: wilty | L3: mask | M3: narvex | N3: rin | O3: saviir | P3: dinokami | Q3: frewe | R3: ruben04 | S3: sombreitor | T3: ad99 | U3: adryx | V3: nico
A4: =TorneosScore!A4 -> CoD3 | B4: =TorneosScore!B4 -> 596 | C4: =TorneosScore!C4 -> 25 | D4: scisto | E4: molo | F4: andhi | G4: gafce | H4: blackloner | I4: ml41 | J4: pichu | K4: tormen | L4: and | M4: chatu | N4: dalvila | O4: ego | P4: wilty | Q4: egotzon | R4: mask | S4: sabo | T4: crotic | U4: diextr | V4: frewe | W4: narvex | X4: ori | Y4: saviir | Z4: traum | AB4: enzoar | AC4: ing3nio
A5: =TorneosScore!A5 -> Estrella | B5: =TorneosScore!B5 -> 410 | C5: =TorneosScore!C5 -> 19 | D5: juancho | E5: gafce | F5: chatu | G5: and | H5: dalvila | I5: golo | J5: default | K5: narvex | L5: aaronssj | M5: diextr | N5: shadow | O5: traum | P5: frewe | Q5: gzuto | R5: leboxi | S5: ori | T5: lonson | U5: salulito | V5: saviir
A6: =TorneosScore!A6 -> CoD2 | B6: =TorneosScore!J6 -> 422 | C6: =TorneosScore!C6 -> 15 | D6: molo | E6: gafce | F6: ramon | G6: juancho | H6: and | I6: jorgito | J6: chatu | K6: dalvila | L6: diextr | M6: egotzon | N6: theros | O6: cuncario | P6: frewe
A7: =TorneosScore!A7 -> Flor | B7: =TorneosScore!B7 -> 366 | C7: =TorneosScore!C7 -> 17 | D7: saihara | E7: ego | F7: zuka | G7: juancho | H7: golo | I7: jorgito | J7: cate | K7: sin0n | L7: chatu | M7: dalvila | N7: gzuto | O7: narvex | P7: dinokami | Q7: wilty | R7: saviir | S7: traum | T7: enzoar
A8: =TorneosScore!A8 -> CoD1 | B8: =TorneosScore!J8 -> 231 | C8: =TorneosScore!C8 -> 11 | D8: tormen | E8: chatu | F8: lego | G8: and | H8: wilty | I8: fongus | J8: hanival | K8: narvex | L8: may | M8: saviir | N8: traum
A9: =TorneosScore!A9 -> Champiñón | B9: =TorneosScore!B9 -> 396 | C9: =TorneosScore!C9 -> 17 | D9: insomnio | E9: ramon | F9: juancho | G9: chatu | H9: azfalot | I9: wilty | J9: narvex | K9: seisde | L9: daviiid_40 | M9: frewe | N9: mask | O9: saviir | P9: berunor | Q9: c4rn4ge | R9: enrique cuadros arce | S9: leboxi | T9: panxino
A10: =TorneosScore!A10 -> TBO17 | B10: =TorneosScore!J10 -> 252 | C10: =TorneosScore!C10 -> 12 | D10: saihara | E10: tormen | F10: juancho | G10: and | H10: chatu | I10: pepitillo | J10: alvagames | K10: wilty | L10: frewe | M10: mask | N10: traum
A11: =TorneosScore!A11 -> TBO16 | B11: =TorneosScore!L11 -> 389 | C11: =TorneosScore!C11 -> 18 | D11: zuka | E11: juancho | F11: golo | G11: ego | H11: chatu | I11: sin0n | J11: wilty | K11: tormen | L11: and | M11: azfalot | N11: cate | O11: lego | P11: ch1ris | Q11: mariorg | R11: narvex | S11: solo | T11: frewe | U11: traum
A12: =TorneosScore!A12 -> TBO15 | B12: =TorneosScore!L12 -> 460 | C12: =TorneosScore!C12 -> 20 | D12: molo | E12: blackloner | F12: saihara | G12: pichu | H12: ego | I12: juancho | J12: chatu | K12: wilty | L12: and | M12: angeloti | N12: golo | O12: tormen | P12: angeleiro | Q12: azfalot | R12: narvex | S12: rin | T12: frewe | U12: peke | V12: sara | W12: traum
A13: =TorneosScore!A13 -> CR4 | B13: =TorneosScore!J13 -> 84 | C13: =TorneosScore!C13 -> 4 | D13: juancho | E13: chatu | F13: and | G13: frewe
A14: =TorneosScore!A14 -> CR3 | B14: =TorneosScore!J14 -> 105 | C14: =TorneosScore!C14 -> 5 | D14: chatu | E14: wilty | F14: narvex | G14: ratope2002 | H14: frewe
A15: =TorneosScore!A15 -> TBO14 | B15: =TorneosScore!L15 -> 350 | C15: =TorneosScore!C15 -> 16 | D15: slogan | E15: juancho | F15: chatu | G15: wilty | H15: azfalot | I15: tora | J15: alvagames | K15: and | L15: foxy | M15: ukon | N15: narvex | O15: rin | P15: dinokami | Q15: frewe | R15: hanival | S15: traum
A16: =TorneosScore!A16 -> CR2 | B16: =TorneosScore!J16 -> 147 | C16: =TorneosScore!C16 -> 7 | D16: slogan | E16: juancho | F16: chatu | G16: and | H16: frewe | I16: tora | J16: rackan
A17: =TorneosScore!A17 -> CR1 | B17: =TorneosScore!J17 -> 105 | C17: =TorneosScore!C17 -> 5 | D17: slogan | E17: lego | F17: and | G17: chatu | H17: frewe
A18: =TorneosScore!A18 -> TBO13 | B18: =TorneosScore!L18 -> 423 | C18: =TorneosScore!C18 -> 18 | D18: rmoragar | E18: chatu | F18: slogan | G18: wilty | H18: juancho | I18: golo | J18: azfalot | K18: lexatiger | L18: and | M18: dalvila | N18: narvex | O18: sin0n | P18: alvagames | Q18: foxy | R18: leboxi | S18: pepitillo | T18: frewe | U18: lego
A19: =TorneosScore!A19 -> TBO12 | B19: =TorneosScore!J19 -> 147 | C19: =TorneosScore!C19 -> 7 | D19: saihara | E19: slogan | F19: wilty | G19: dalvila | H19: alvagames | I19: and | J19: narvex
A21: =D21+E21+F21 -> 100 | B21: <8 entrants | C21: =100/3 -> 33.333333 | D21: =C21*1.5 -> 50 | E21: =C21*1 -> 33.333333 | F21: =C21*0.5 -> 16.666667
A22: =D22+E22+F22+G22+H22+J22 -> 100 | B22: <16 entrants | C22: =100/8 -> 12.5 | D22: =C22*2 -> 25 | E22: =C22*1.75 -> 21.875 | F22: =C22*1.5 -> 18.75 | G22: =C22*1.25 -> 15.625 | H22: =C22*1 -> 12.5 | I22: =H22 -> 12.5 | J22: =C22*0.5 -> 6.25 | K22: =J22 -> 6.25
A23: =D23+E23+F23+G23+H23+J23+L23 -> 100 | B23: >=16 entrants | C23: =100/12 -> 8.3333333 | D23: =C23*3 -> 25 | E23: =C23*2.5 -> 20.833333 | F23: =C23*2 -> 16.666667 | G23: =C23*1.5 -> 12.5 | H23: =C23*1.25 -> 10.416667 | I23: =H23 -> 10.416667 | J23: =C23*1 -> 8.3333333 | K23: =J23 -> 8.3333333 | L23: =C23*0.75 -> 6.25 | M23: =L23 -> 6.25 | N23: =L23 -> 6.25 | O23: =L23 -> 6.25
A25: =A1 -> Torneo | B25: =C1 -> Entrants | C25: Score/entrant | D25: 1 | E25: 2 | F25: 3 | G25: 4 | H25: 5 | I25: 5 | J25: 7 | K25: 7 | L25: 9 | M25: 9 | N25: 9 | O25: 9 | P25: Score total | Q25: Suma valores
A26: =A2 -> CoD4 | B26: =C2 -> 16 | C26: =B2/12 -> 35.166667 | D26: =C26*3 -> 105.5 | E26: =C26*2.5 -> 87.916667 | F26: =C26*2 -> 70.333333 | G26: =C26*1.5 -> 52.75 | H26: =C26*1.25 -> 43.958333 | I26: =H26 -> 43.958333 | J26: =C26*1 -> 35.166667 | K26: =J26 -> 35.166667 | L26: =C26*0.75 -> 26.375 | M26: =L26 -> 26.375 | N26: =L26 -> 26.375 | O26: =L26 -> 26.375 | P26: =B2 -> 422 | Q26: =D26+E26+F26+G26+H26+J26+L26 -> 422
A27: =A3 -> Corona | B27: =C3 -> 19 | C27: =B3/12 -> 33.166667 | D27: =C27*3 -> 99.5 | E27: =C27*2.5 -> 82.916667 | F27: =C27*2 -> 66.333333 | G27: =C27*1.5 -> 49.75 | H27: =C27*1.25 -> 41.458333 | I27: =H27 -> 41.458333 | J27: =C27*1 -> 33.166667 | K27: =J27 -> 33.166667 | L27: =C27*0.75 -> 24.875 | M27: =L27 -> 24.875 | N27: =L27 -> 24.875 | O27: =L27 -> 24.875 | P27: =B3 -> 398 | Q27: =D27+E27+F27+G27+H27+J27+L27 -> 398
A28: =A4 -> CoD3 | B28: =C4 -> 25 | C28: =B4/12 -> 49.666667 | D28: =C28*3 -> 149 | E28: =C28*2.5 -> 124.16667 | F28: =C28*2 -> 99.333333 | G28: =C28*1.5 -> 74.5 | H28: =C28*1.25 -> 62.083333 | I28: =H28 -> 62.083333 | J28: =C28*1 -> 49.666667 | K28: =J28 -> 49.666667 | L28: =C28*0.75 -> 37.25 | M28: =L28 -> 37.25 | N28: =L28 -> 37.25 | O28: =L28 -> 37.25 | P28: =B4 -> 596 | Q28: =D28+E28+F28+G28+H28+J28+L28 -> 596
A29: =A5 -> Estrella | B29: =C5 -> 19 | C29: =B5/12 -> 34.166667 | D29: =C29*3 -> 102.5 | E29: =C29*2.5 -> 85.416667 | F29: =C29*2 -> 68.333333 | G29: =C29*1.5 -> 51.25 | H29: =C29*1.25 -> 42.708333 | I29: =H29 -> 42.708333 | J29: =C29*1 -> 34.166667 | K29: =J29 -> 34.166667 | L29: =C29*0.75 -> 25.625 | M29: =L29 -> 25.625 | N29: =L29 -> 25.625 | O29: =L29 -> 25.625 | P29: =B5 -> 410 | Q29: =D29+E29+F29+G29+H29+J29+L29 -> 410
A30: =A6 -> CoD2 | B30: =C6 -> 15 | C30: =B6/12 -> 35.166667 | D30: =C30*3 -> 105.5 | E30: =C30*2.5 -> 87.916667 | F30: =C30*2 -> 70.333333 | G30: =C30*1.5 -> 52.75 | H30: =C30*1.25 -> 43.958333 | I30: =H30 -> 43.958333 | J30: =C30*1 -> 35.166667 | K30: =J30 -> 35.166667 | L30: =C30*0.75 -> 26.375 | M30: =L30 -> 26.375 | N30: =L30 -> 26.375 | O30: =L30 -> 26.375 | P30: =B6 -> 422 | Q30: =D30+E30+F30+G30+H30+J30+L30 -> 422
A31: =A7 -> Flor | B31: =C7 -> 17 | C31: =B7/12 -> 30.5 | D31: =C31*3 -> 91.5 | E31: =C31*2.5 -> 76.25 | F31: =C31*2 -> 61 | G31: =C31*1.5 -> 45.75 | H31: =C31*1.25 -> 38.125 | I31: =H31 -> 38.125 | J31: =C31*1 -> 30.5 | K31: =J31 -> 30.5 | L31: =C31*0.75 -> 22.875 | M31: =L31 -> 22.875 | N31: =L31 -> 22.875 | O31: =L31 -> 22.875 | P31: =B7 -> 366 | Q31: =D31+E31+F31+G31+H31+J31+L31 -> 366
A32: =A8 -> CoD1 | B32: =C8 -> 11 | C32: =B8/8 -> 28.875 | D32: =C32*2 -> 57.75 | E32: =C32*1.75 -> 50.53125 | F32: =C32*1.5 -> 43.3125 | G32: =C32*1.25 -> 36.09375 | H32: =C32*1 -> 28.875 | I32: =H32 -> 28.875 | J32: =C32*0.5 -> 14.4375 | K32: =J32 -> 14.4375 | P32: =B8 -> 231 | Q32: =D32+E32+F32+G32+H32+J32+L32 -> 231
A33: =A9 -> Champiñón | B33: =C9 -> 17 | C33: =B9/12 -> 33 | D33: =C33*3 -> 99 | E33: =C33*2.5 -> 82.5 | F33: =C33*2 -> 66 | G33: =C33*1.5 -> 49.5 | H33: =C33*1.25 -> 41.25 | I33: =H33 -> 41.25 | J33: =C33*1 -> 33 | K33: =J33 -> 33 | L33: =C33*0.75 -> 24.75 | M33: =L33 -> 24.75 | N33: =L33 -> 24.75 | O33: =L33 -> 24.75 | P33: =B9 -> 396 | Q33: =D33+E33+F33+G33+H33+J33+L33 -> 396
A34: =A10 -> TBO17 | B34: =C10 -> 12 | C34: =B10/8 -> 31.5 | D34: =C34*2 -> 63 | E34: =C34*1.75 -> 55.125 | F34: =C34*1.5 -> 47.25 | G34: =C34*1.25 -> 39.375 | H34: =C34*1 -> 31.5 | I34: =H34 -> 31.5 | J34: =C34*0.5 -> 15.75 | K34: =J34 -> 15.75 | P34: =B10 -> 252 | Q34: =D34+E34+F34+G34+H34+J34+L34 -> 252
A35: =A11 -> TBO16 | B35: =C11 -> 18 | C35: =B11/12 -> 32.416667 | D35: =C35*3 -> 97.25 | E35: =C35*2.5 -> 81.041667 | F35: =C35*2 -> 64.833333 | G35: =C35*1.5 -> 48.625 | H35: =C35*1.25 -> 40.520833 | I35: =H35 -> 40.520833 | J35: =C35*1 -> 32.416667 | K35: =J35 -> 32.416667 | L35: =C35*0.75 -> 24.3125 | M35: =L35 -> 24.3125 | N35: =L35 -> 24.3125 | O35: =L35 -> 24.3125 | P35: =B11 -> 389 | Q35: =D35+E35+F35+G35+H35+J35+L35 -> 389
A36: =A12 -> TBO15 | B36: =C12 -> 20 | C36: =B12/12 -> 38.333333 | D36: =C36*3 -> 115 | E36: =C36*2.5 -> 95.833333 | F36: =C36*2 -> 76.666667 | G36: =C36*1.5 -> 57.5 | H36: =C36*1.25 -> 47.916667 | I36: =H36 -> 47.916667 | J36: =C36*1 -> 38.333333 | K36: =J36 -> 38.333333 | L36: =C36*0.75 -> 28.75 | M36: =L36 -> 28.75 | N36: =L36 -> 28.75 | O36: =L36 -> 28.75 | P36: =B12 -> 460 | Q36: =D36+E36+F36+G36+H36+J36+L36 -> 460
A37: =A13 -> CR4 | B37: =C13 -> 4 | C37: =B13/3 -> 28 | D37: =C37*1.5 -> 42 | E37: =C37*1 -> 28 | F37: =C37*0.5 -> 14 | P37: =B13 -> 84 | Q37: =D37+E37+F37+G37+H37+J37+L37 -> 84
A38: =A14 -> CR3 | B38: =C14 -> 5 | C38: =B14/3 -> 35 | D38: =C38*1.5 -> 52.5 | E38: =C38*1 -> 35 | F38: =C38*0.5 -> 17.5 | P38: =B14 -> 105 | Q38: =D38+E38+F38+G38+H38+J38+L38 -> 105
A39: =A15 -> TBO14 | B39: =C15 -> 16 | C39: =B15/12 -> 29.166667 | D39: =C39*3 -> 87.5 | E39: =C39*2.5 -> 72.916667 | F39: =C39*2 -> 58.333333 | G39: =C39*1.5 -> 43.75 | H39: =C39*1.25 -> 36.458333 | I39: =H39 -> 36.458333 | J39: =C39*1 -> 29.166667 | K39: =J39 -> 29.166667 | L39: =C39*0.75 -> 21.875 | M39: =L39 -> 21.875 | N39: =L39 -> 21.875 | O39: =L39 -> 21.875 | P39: =B15 -> 350 | Q39: =D39+E39+F39+G39+H39+J39+L39 -> 350
A40: =A16 -> CR2 | B40: =C16 -> 7 | C40: =B16/3 -> 49 | D40: =C40*1.5 -> 73.5 | E40: =C40*1 -> 49 | F40: =C40*0.5 -> 24.5 | P40: =B16 -> 147 | Q40: =D40+E40+F40+G40+H40+J40+L40 -> 147
A41: =A17 -> CR1 | B41: =C17 -> 5 | C41: =B17/3 -> 35 | D41: =C41*1.5 -> 52.5 | E41: =C41*1 -> 35 | F41: =C41*0.5 -> 17.5 | P41: =B17 -> 105 | Q41: =D41+E41+F41+G41+H41+J41+L41 -> 105
A42: =A18 -> TBO13 | B42: =C18 -> 18 | C42: =B18/12 -> 35.25 | D42: =C42*3 -> 105.75 | E42: =C42*2.5 -> 88.125 | F42: =C42*2 -> 70.5 | G42: =C42*1.5 -> 52.875 | H42: =C42*1.25 -> 44.0625 | I42: =H42 -> 44.0625 | J42: =C42*1 -> 35.25 | K42: =J42 -> 35.25 | L42: =C42*0.75 -> 26.4375 | M42: =L42 -> 26.4375 | N42: =L42 -> 26.4375 | O42: =L42 -> 26.4375 | P42: =B18 -> 423 | Q42: =D42+E42+F42+G42+H42+J42+L42 -> 423
...

Sheet PlayerResults
A1: Torneo | B1: Saihara | C1: El Juancho | D1: Slogan | E1: Tormen | F1: chatu | G1: AND | H1: DrWilty | I1: Lego | J1: Azfalot | K1: Dalvila | L1: Narvex | M1: Diextr79 | N1: Mask | O1: Rin | P1: Saviir | Q1: AlvaGames99 | R1: Traum | S1: Frewe10 | T1: Foxy | U1: Dinokami | V1: Ing3nio | W1: Leboxi | X1: Tora
A2: =TorneosScore!A2 -> CoD4 | B2: X | C2: 3 | D2: X | E2: 5 | F2: 5 | G2: 7 | H2: 9 | I2: X | J2: X | K2: X | L2: 13 | M2: 13 | N2: X | O2: 9 | P2: 13 | Q2: X | R2: 9 | S2: X | T2: X | U2: X | V2: 13 | W2: X | X2: X
A3: =TorneosScore!A3 -> Corona | B3: 1 | C3: 2 | D3: X | E3: 5 | F3: 4 | G3: 3 | H3: 7 | I3: X | J3: X | K3: 5 | L3: 9 | M3: 7 | N3: 9 | O3: 9 | P3: 9 | Q3: X | R3: X | S3: 13 | T3: X | U3: 13 | V3: X | W3: X | X3: X
A4: =TorneosScore!A4 -> CoD3 | B4: X | C4: X | D4: X | E4: 7 | F4: 9 | G4: 9 | H4: 13 | I4: X | J4: X | K4: 9 | L4: 17 | M4: 17 | N4: 13 | O4: X | P4: 17 | Q4: X | R4: 17 | S4: 17 | T4: X | U4: X | V4: 17 | W4: X | X4: X
A5: =TorneosScore!A5 -> Estrella | B5: X | C5: 1 | D5: X | E5: X | F5: 3 | G5: 4 | H5: X | I5: X | J5: X | K5: 5 | L5: 7 | M5: 9 | N5: X | O5: X | P5: 17 | Q5: X | R5: 9 | S5: 13 | T5: X | U5: X | V5: X | W5: 13 | X5: X
A6: =TorneosScore!A6 -> CoD2 | B6: X | C6: 4 | D6: X | E6: X | F6: 7 | G6: 5 | H6: X | I6: X | J6: X | K6: 7 | L6: X | M6: 9 | N6: X | O6: X | P6: X | Q6: X | R6: X | S6: 13 | T6: X | U6: X | V6: X | W6: X | X6: X
A7: =TorneosScore!A7 -> Flor | B7: 1 | C7: 4 | D7: X | E7: X | F7: 9 | G7: X | H7: 13 | I7: X | J7: X | K7: 9 | L7: 9 | M7: X | N7: X | O7: X | P7: 13 | Q7: X | R7: 13 | S7: X | T7: X | U7: 13 | V7: X | W7: X | X7: X
A8: =TorneosScore!A8 -> CoD1 | B8: X | C8: X | D8: X | E8: 1 | F8: 2 | G8: 4 | H8: 5 | I8: 3 | J8: X | K8: X | L8: 7 | M8: X | N8: X | O8: X | P8: 9 | Q8: X | R8: 9 | S8: X | T8: X | U8: X | V8: X | W8: X | X8: X
A9: =TorneosScore!A9 -> Champiñón | B9: X | C9: 3 | D9: X | E9: X | F9: 4 | G9: X | H9: 5 | I9: X | J9: 5 | K9: X | L9: 7 | M9: X | N9: 9 | O9: X | P9: 9 | Q9: X | R9: X | S9: 9 | T9: X | U9: X | V9: X | W9: 13 | X9: X
A10: =TorneosScore!A10 -> TBO17 | B10: 1 | C10: 3 | D10: X | E10: 2 | F10: 5 | G10: 4 | H10: 7 | I10: X | J10: X | K10: X | L10: X | M10: X | N10: 9 | O10: X | P10: X | Q10: 7 | R10: 9 | S10: 9 | T10: X | U10: X | V10: X | W10: X | X10: X
A11: =TorneosScore!A11 -> TBO16 | B11: X | C11: 2 | D11: X | E11: 7 | F11: 5 | G11: 9 | H11: 7 | I11: 9 | J11: 9 | K11: X | L11: 13 | M11: X | N11: X | O11: X | P11: X | Q11: X | R11: 17 | S11: 17 | T11: X | U11: X | V11: X | W11: X | X11: X
A12: =TorneosScore!A12 -> TBO15 | B12: 3 | C12: 5 | D12: X | E12: 9 | F12: 7 | G12: 9 | H12: 7 | I12: X | J12: 13 | K12: X | L12: 13 | M12: X | N12: X | O12: 13 | P12: X | Q12: X | R12: 17 | S12: 17 | T12: X | U12: X | V12: X | W12: X | X12: X
A13: =TorneosScore!A13 -> CR4 | B13: X | C13: 1 | D13: X | E13: X | F13: 2 | G13: 3 | H13: X | I13: X | J13: X | K13: X | L13: X | M13: X | N13: X | O13: X | P13: X | Q13: X | R13: X | S13: 4 | T13: X | U13: X | V13: X | W13: X | X13: X
A14: =TorneosScore!A14 -> CR3 | B14: X | C14: X | D14: X | E14: X | F14: 1 | G14: X | H14: 2 | I14: X | J14: X | K14: X | L14: 3 | M14: X | N14: X | O14: X | P14: X | Q14: X | R14: X | S14: 5 | T14: X | U14: X | V14: X | W14: X | X14: X
A15: =TorneosScore!A15 -> TBO14 | B15: X | C15: 2 | D15: 1 | E15: X | F15: 3 | G15: 7 | H15: 4 | I15: X | J15: 5 | K15: X | L15: 9 | M15: X | N15: X | O15: 9 | P15: X | Q15: 7 | R15: 13 | S15: 13 | T15: 9 | U15: 13 | V15: X | W15: X | X15: 5
A16: =TorneosScore!A16 -> CR2 | B16: X | C16: 2 | D16: 1 | E16: X | F16: 3 | G16: 4 | H16: X | I16: X | J16: X | K16: X | L16: X | M16: X | N16: X | O16: X | P16: X | Q16: X | R16: X | S16: 5 | T16: X | U16: X | V16: X | W16: X | X16: 5
A17: =TorneosScore!A17 -> CR1 | B17: X | C17: X | D17: 1 | E17: X | F17: 4 | G17: 3 | H17: X | I17: 2 | J17: X | K17: X | L17: X | M17: X | N17: X | O17: X | P17: X | Q17: X | R17: X | S17: 5 | T17: X | U17: X | V17: X | W17: X | X17: X
A18: =TorneosScore!A18 -> TBO13 | B18: X | C18: 5 | D18: 3 | E18: X | F18: 2 | G18: 9 | H18: 4 | I18: 17 | J18: 7 | K18: 9 | L18: 9 | M18: X | N18: X | O18: X | P18: X | Q18: 13 | R18: X | S18: 17 | T18: 13 | U18: X | V18: X | W18: 13 | X18: X
A19: =TorneosScore!A19 -> TBO12 | B19: 1 | C19: X | D19: 2 | E19: X | F19: X | G19: 5 | H19: 3 | I19: X | J19: X | K19: X | L19: 7 | M19: X | N19: X | O19: X | P19: X | Q19: 5 | R19: X | S19: X | T19: X | U19: X | V19: X | W19: X | X19: X
A21: Score | B21: Saihara | C21: El Juancho | D21: Slogan | E21: Tormen | F21: chatu | G21: AND | H21: DrWilty | I21: Lego | J21: Azfalot | K21: Dalvila | L21: Narvex | M21: Diextr79 | N21: Mask | O21: Rin | P21: Saviir | Q21: AlvaGames99 | R21: Traum | S21: Frewe10 | T21: Foxy | U21: Dinokami | V21: Ing3nio | W21: Leboxi | X21: Tora
A22: =TorneosScore!A2 -> CoD4 | B22: X | C22: =TorneosResults!F26 -> 70.333333 | D22: X | E22: =TorneosResults!H26 -> 43.958333 | F22: =TorneosResults!H26 -> 43.958333 | G22: =TorneosResults!J26 -> 35.166667 | H22: =TorneosResults!L26 -> 26.375 | I22: X | J22: X | K22: X | L22: 0 | M22: 0 | N22: X | O22: =TorneosResults!L26 -> 26.375 | P22: 0 | Q22: X | R22: =TorneosResults!L26 -> 26.375 | S22: X | T22: X | U22: X | V22: 0 | W22: X | X22: X
A23: =TorneosScore!A3 -> Corona | B23: =TorneosResults!D27 -> 99.5 | C23: =TorneosResults!E27 -> 82.916667 | D23: X | E23: =TorneosResults!H27 -> 41.458333 | F23: =TorneosResults!G27 -> 49.75 | G23: =TorneosResults!F27 -> 66.333333 | H23: =TorneosResults!J27 -> 33.166667 | I23: X | J23: X | K23: =TorneosResults!H27 -> 41.458333 | L23: =TorneosResults!L27 -> 24.875 | M23: =TorneosResults!J27 -> 33.166667 | N23: =TorneosResults!L27 -> 24.875 | O23: =TorneosResults!L27 -> 24.875 | P23: =TorneosResults!L27 -> 24.875 | Q23: X | R23: X | S23: 0 | T23: X | U23: 0 | V23: X | W23: X | X23: X
A24: =TorneosScore!A4 -> CoD3 | B24: X | C24: X | D24: X | E24: =TorneosResults!J28 -> 49.666667 | F24: =TorneosResults!L28 -> 37.25 | G24: =TorneosResults!L28 -> 37.25 | H24: 0 | I24: X | J24: X | K24: =TorneosResults!L28 -> 37.25 | L24: 0 | M24: 0 | N24: 0 | O24: X | P24: 0 | Q24: X | R24: 0 | S24: 0 | T24: X | U24: X | V24: 0 | W24: X | X24: X
A25: =TorneosScore!A5 -> Estrella | B25: X | C25: =TorneosResults!D29 -> 102.5 | D25: X | E25: X | F25: =TorneosResults!F29 -> 68.333333 | G25: =TorneosResults!G29 -> 51.25 | H25: X | I25: X | J25: X | K25: =TorneosResults!H29 -> 42.708333 | L25: =TorneosResults!J29 -> 34.166667 | M25: =TorneosResults!L29 -> 25.625 | N25: X | O25: X | P25: 0 | Q25: X | R25: =TorneosResults!L29 -> 25.625 | S25: 0 | T25: X | U25: X | V25: X | W25: 0 | X25: X
A26: =TorneosScore!A6 -> CoD2 | B26: X | C26: =TorneosResults!G30 -> 52.75 | D26: X | E26: X | F26: =TorneosResults!J30 -> 35.166667 | G26: =TorneosResults!H30 -> 43.958333 | H26: X | I26: X | J26: X | K26: =TorneosResults!J30 -> 35.166667 | L26: X | M26: =TorneosResults!L30 -> 26.375 | N26: X | O26: X | P26: X | Q26: X | R26: X | S26: 0 | T26: X | U26: X | V26: X | W26: X | X26: X
A27: =TorneosScore!A7 -> Flor | B27: =TorneosResults!D31 -> 91.5 | C27: =TorneosResults!G31 -> 45.75 | D27: X | E27: X | F27: =TorneosResults!L31 -> 22.875 | G27: X | H27: 0 | I27: X | J27: X | K27: =TorneosResults!L31 -> 22.875 | L27: =TorneosResults!L31 -> 22.875 | M27: X | N27: X | O27: X | P27: 0 | Q27: X | R27: 0 | S27: X | T27: X | U27: 0 | V27: X | W27: X | X27: X
A28: =TorneosScore!A8 -> CoD1 | B28: X | C28: X | D28: X | E28: =TorneosResults!D32 -> 57.75 | F28: =TorneosResults!E32 -> 50.53125 | G28: =TorneosResults!G32 -> 36.09375 | H28: =TorneosResults!H32 -> 28.875 | I28: =TorneosResults!F32 -> 43.3125 | J28: X | K28: X | L28: =TorneosResults!J32 -> 14.4375 | M28: X | N28: X | O28: X | P28: 0 | Q28: X | R28: 0 | S28: X | T28: X | U28: X | V28: X | W28: X | X28: X
A29: =TorneosScore!A9 -> Champiñón | B29: X | C29: =TorneosResults!F33 -> 66 | D29: X | E29: X | F29: =TorneosResults!G33 -> 49.5 | G29: X | H29: =TorneosResults!H33 -> 41.25 | I29: X | J29: =TorneosResults!H33 -> 41.25 | K29: X | L29: =TorneosResults!J33 -> 33 | M29: X | N29: =TorneosResults!L33 -> 24.75 | O29: X | P29: =TorneosResults!L33 -> 24.75 | Q29: X | R29: X | S29: =TorneosResults!L33 -> 24.75 | T29: X | U29: X | V29: X | W29: 0 | X29: X
A30: =TorneosScore!A10 -> TBO17 | B30: =TorneosResults!D34 -> 63 | C30: =TorneosResults!F34 -> 47.25 | D30: X | E30: =TorneosResults!E34 -> 55.125 | F30: =TorneosResults!H34 -> 31.5 | G30: =TorneosResults!G34 -> 39.375 | H30: =TorneosResults!J34 -> 15.75 | I30: X | J30: X | K30: X | L30: X | M30: X | N30: 0 | O30: X | P30: X | Q30: =TorneosResults!J34 -> 15.75 | R30: 0 | S30: 0 | T30: X | U30: X | V30: X | W30: X | X30: X
A31: =TorneosScore!A11 -> TBO16 | B31: X | C31: =TorneosResults!E35 -> 81.041667 | D31: X | E31: =TorneosResults!J35 -> 32.416667 | F31: =TorneosResults!H35 -> 40.520833 | G31: =TorneosResults!L35 -> 24.3125 | H31: =TorneosResults!J35 -> 32.416667 | I31: =TorneosResults!L35 -> 24.3125 | J31: =TorneosResults!L35 -> 24.3125 | K31: X | L31: 0 | M31: X | N31: X | O31: X | P31: X | Q31: X | R31: 0 | S31: 0 | T31: X | U31: X | V31: X | W31: X | X31: X
A32: =TorneosScore!A12 -> TBO15 | B32: =TorneosResults!F36 -> 76.666667 | C32: =TorneosResults!H36 -> 47.916667 | D32: X | E32: =TorneosResults!L36 -> 28.75 | F32: =TorneosResults!J36 -> 38.333333 | G32: =TorneosResults!L36 -> 28.75 | H32: =TorneosResults!J36 -> 38.333333 | I32: X | J32: 0 | K32: X | L32: 0 | M32: X | N32: X | O32: 0 | P32: X | Q32: X | R32: 0 | S32: 0 | T32: X | U32: X | V32: X | W32: X | X32: X
A33: =TorneosScore!A13 -> CR4 | B33: X | C33: =TorneosResults!D37 -> 42 | D33: X | E33: X | F33: =TorneosResults!E37 -> 28 | G33: =TorneosResults!F37 -> 14 | H33: X | I33: X | J33: X | K33: X | L33: X | M33: X | N33: X | O33: X | P33: X | Q33: X | R33: X | S33: 0 | T33: X | U33: X | V33: X | W33: X | X33: X
A34: =TorneosScore!A14 -> CR3 | B34: X | C34: X | D34: X | E34: X | F34: =TorneosResults!D38 -> 52.5 | G34: X | H34: =TorneosResults!E38 -> 35 | I34: X | J34: X | K34: X | L34: =TorneosResults!F38 -> 17.5 | M34: X | N34: X | O34: X | P34: X | Q34: X | R34: X | S34: 0 | T34: X | U34: X | V34: X | W34: X | X34: X
A35: =TorneosScore!A15 -> TBO14 | B35: X | C35: =TorneosResults!E39 -> 72.916667 | D35: =TorneosResults!D39 -> 87.5 | E35: X | F35: =TorneosResults!F39 -> 58.333333 | G35: =TorneosResults!J39 -> 29.166667 | H35: =TorneosResults!G39 -> 43.75 | I35: X | J35: =TorneosResults!H39 -> 36.458333 | K35: X | L35: =TorneosResults!L39 -> 21.875 | M35: X | N35: X | O35: =TorneosResults!L39 -> 21.875 | P35: X | Q35: =TorneosResults!J39 -> 29.166667 | R35: 0 | S35: 0 | T35: =TorneosResults!L39 -> 21.875 | U35: 0 | V35: X | W35: X | X35: =TorneosResults!H39 -> 36.458333
A36: =TorneosScore!A16 -> CR2 | B36: X | C36: =TorneosResults!E40 -> 49 | D36: =TorneosResults!D40 -> 73.5 | E36: X | F36: =TorneosResults!F40 -> 24.5 | G36: 0 | H36: X | I36: X | J36: X | K36: X | L36: X | M36: X | N36: X | O36: X | P36: X | Q36: X | R36: X | S36: 0 | T36: X | U36: X | V36: X | W36: X | X36: 0
A37: =TorneosScore!A17 -> CR1 | B37: X | C37: X | D37: =TorneosResults!D41 -> 52.5 | E37: X | F37: 0 | G37: =TorneosResults!F41 -> 17.5 | H37: X | I37: =TorneosResults!E41 -> 35 | J37: X | K37: X | L37: X | M37: X | N37: X | O37: X | P37: X | Q37: X | R37: X | S37: 0 | T37: X | U37: X | V37: X | W37: X | X37: X
A38: =TorneosScore!A18 -> TBO13 | B38: X | C38: =TorneosResults!H42 -> 44.0625 | D38: =TorneosResults!F42 -> 70.5 | E38: X | F38: =TorneosResults!E42 -> 88.125 | G38: =TorneosResults!L42 -> 26.4375 | H38: =TorneosResults!G42 -> 52.875 | I38: 0 | J38: =TorneosResults!J42 -> 35.25 | K38: =TorneosResults!L42 -> 26.4375 | L38: =TorneosResults!L42 -> 26.4375 | M38: X | N38: X | O38: X | P38: X | Q38: 0 | R38: X | S38: 0 | T38: 0 | U38: X | V38: X | W38: 0 | X38: X
A39: =TorneosScore!A19 -> TBO12 | B39: =TorneosResults!D43 -> 73.5 | C39: X | D39: =TorneosResults!E43 -> 49 | E39: X | F39: X | G39: 0 | H39: =TorneosResults!F43 -> 24.5 | I39: X | J39: X | K39: X | L39: 0 | M39: X | N39: X | O39: X | P39: X | Q39: 0 | R39: X | S39: X | T39: X | U39: X | V39: X | W39: X | X39: X
B41: =B23 -> 99.5 | C41: =C25 -> 102.5 | D41: =D35 -> 87.5 | E41: =E28 -> 57.75 | F41: =F38 -> 88.125 | G41: =G23 -> 66.333333 | H41: =H38 -> 52.875 | I41: =I28 -> 43.3125 | J41: =J29 -> 41.25 | K41: =K25 -> 42.708333 | L41: =L25 -> 34.166667 | M41: =M23 -> 33.166667 | N41: =N23 -> 24.875 | O41: =O22 -> 26.375 | P41: =P23 -> 24.875 | Q41: =Q35 -> 29.166667 | R41: =R22 -> 26.375 | S41: =S29 -> 24.75 | T41: =T35 -> 21.875 | U41: 0 | V41: 0 | W41: 0 | X41: =X35 -> 36.458333
B42: =B27 -> 91.5 | C42: =C23 -> 82.916667 | D42: =D36 -> 73.5 | E42: =E30 -> 55.125 | F42: =F25 -> 68.333333 | G42: =G25 -> 51.25 | H42: =H35 -> 43.75 | I42: =I37 -> 35 | J42: =J35 -> 36.458333 | K42: =K23 -> 41.458333 | L42: =L29 -> 33 | M42: =M26 -> 26.375 | N42: =N29 -> 24.75 | O42: =O23 -> 24.875 | P42: =P29 -> 24.75 | Q42: =Q30 -> 15.75 | R42: =R25 -> 25.625
...

Sheet PuntosBraacket
A1: Saihara | B1: 6504
A2: El Juancho | B2: 5971
A3: Slogan | B3: 5498
A4: Tormen | B4: 5277
A5: chatu | B5: 5180
A6: AND | B6: 4665
A7: DrWilty | B7: 4222
A8: Lego | B8: 4157
A9: Azfalot | B9: 3665
A10: Dalvila | B10: 3595
A11: Narvex | B11: 2772
A12: Diextr79 | B12: 2637
... A23: Tora | B23: 2763
